Workbook

Sheet ROK Prev MV
B2: Prehľad prevádzky motoroveho vozidla | L2: za ROK | M2: 2025 | O2: CP BB
B4: EČV: | C4: BB215GN | F4: Palivo | H4: PHM | I4: 9.5 | J4: A (vonku) | L4: Objem nadrže
B5: TYP: | C5: dodávka | F5: Diesel | G5: BA | H5: Norma | I5: 10.5 | J5: C (mesto) | L5: 90
L6: STAV NÁDRŽ
B7: ID voz. | C7: B45539 | F7: STAV | G7: TACHOMETER | L7: Začiatok | M7: Koniec
F8: Začiatok | H8: Koniec | L8: 79.69 | M8: =O26 -> 88.025 | N8: L
F9: 30109 | H9: =O14+F9 -> 33144 | M9: =(L9+O31)-O19 -> 60.981815 | N9: €
B10: Odjazdené kilometre | O10: Odjazdené kilometre
B11: za Mes. | C11: 1 | D11: 2 | E11: 3 | F11: 4 | G11: 5 | H11: 6 | I11: 7 | J11: 8 | K11: 9 | L11: 10 | M11: 11 | N11: 12 | O11: Spolu
B12: Mesto | C12: ='01'!B$46 -> 147 | D12: ='02'!$B$46 -> 101 | E12: ='03'!$B$46 -> 83 | F12: ='04'!$B$46 -> 184 | G12: ='05'!$B$46 -> 113 | H12: ='06'!$B$46 -> 83 | I12: ='07'!$B$46 -> 73 | J12: ='08'!$B$46 -> 314 | K12: ='09'!$B$46 -> 178 | L12: ='10'!$B$46 -> 146 | M12: ='11'!$B$46 -> 52 | N12: ='12'!$B$46 -> 10 | O12: =SUM(C12:N12) -> 1484 | P12: km
B13: Vonku | C13: ='01'!C$46 -> 20 | D13: ='02'!$C$46 -> 50 | E13: ='03'!$C$46 -> 65 | F13: ='04'!$C$46 -> 500 | G13: ='05'!$C$46 -> 110 | H13: ='06'!$C$46 -> 0 | I13: ='07'!$C$46 -> 10 | J13: ='08'!$C$46 -> 658 | K13: ='09'!$C$46 -> 78 | L13: ='10'!$C$46 -> 30 | M13: ='11'!$C$46 -> 30 | N13: ='12'!$C$46 -> 0 | O13: =SUM(C13:N13) -> 1551 | P13: km
B14: Spolu | C14: ='01'!D$46 -> 167 | D14: ='02'!$D$46 -> 151 | E14: ='03'!$D$46 -> 148 | F14: ='04'!$D$46 -> 684 | G14: ='05'!$D$46 -> 223 | H14: ='06'!$D$46 -> 83 | I14: ='07'!$D$46 -> 83 | J14: ='08'!$D$46 -> 972 | K14: ='09'!$D$46 -> 256 | L14: ='10'!$D$46 -> 176 | M14: ='11'!$D$46 -> 82 | N14: ='12'!$D$46 -> 10 | O14: =SUM(C14:N14) -> 3035 | P14: km
B16: Spotreba PHM | O16: Spotreba PHM
B17: za Mes. | C17: 1 | D17: 2 | E17: 3 | F17: 4 | G17: 5 | H17: 6 | I17: 7 | J17: 8 | K17: 9 | L17: 10 | M17: 11 | N17: 12 | O17: Spolu
B18: (lit) | C18: ='01'!I$46 -> 17.335 | D18: ='02'!I$46 -> 15.355 | E18: ='03'!I$46 -> 14.89 | F18: ='04'!I$46 -> 66.82 | G18: ='05'!I$46 -> 22.315 | H18: ='06'!I$46 -> 8.715 | I18: ='07'!I$46 -> 8.615 | J18: ='08'!I$46 -> 95.48 | K18: ='09'!I$46 -> 26.1 | L18: ='10'!I$46 -> 18.18 | M18: ='11'!I$46 -> 8.31 | N18: ='12'!J$46 -> 53 | O18: =SUM(C18:N18) -> 355.115 | P18: lit
B19: (€) | C19: ='01'!I$50 -> 0 | D19: ='02'!I$50 -> 0 | E19: ='03'!I$50 -> 12.00134 | F19: ='04'!I$50 -> 71.96514 | G19: ='05'!I$50 -> 24.033255 | H19: ='06'!I$50 -> 9.386055 | I19: ='07'!I$50 -> 9.278355 | J19: ='08'!I$50 -> 92.80656 | K19: ='09'!I$50 -> 25.3692 | L19: ='10'!I$50 -> 17.67096 | M19: ='11'!I$50 -> 8.07732 | N19: ='12'!J$50 -> 53 | O19: =SUM(C19:N19) -> 323.58818 | P19: €ur
B20: Priemerná spotreba | O20: Priemerná spotreba
B21: za Mes. | C21: 1 | D21: 2 | E21: 3 | F21: 4 | G21: 5 | H21: 6 | I21: 7 | J21: 8 | K21: 9 | L21: 10 | M21: 11 | N21: 12 | O21: celková
B22: na100km | C22: =IF(C14>0,(C18/C14)*100,0) -> 10.38024 | D22: =IF(D14>0,(D18/D14)*100,0) -> 10.168874 | E22: =IF(E14>0,(E18/E14)*100,0) -> 10.060811 | F22: =IF(F14>0,(F18/F14)*100,0) -> 9.7690058 | G22: =IF(G14>0,(G18/G14)*100,0) -> 10.006726 | H22: =IF(H14>0,(H18/H14)*100,0) -> 10.5 | I22: =IF(I14>0,(I18/I14)*100,0) -> 10.379518 | J22: =IF(J14>0,(J18/J14)*100,0) -> 9.8230453 | ... O22: =IF(O14>0,(O18/O14)*100,0) -> 11.700659 | P22: lit
B24: Nádrž stav na konci mes. | O24: Nádrž stav na konci
B25: za Mes. | C25: 1 | D25: 2 | E25: 3 | F25: 4 | G25: 5 | H25: 6 | I25: 7 | J25: 8 | K25: 9 | L25: 10 | M25: 11 | N25: 12
B26: (lit) | C26: =IF(C14>0,'01'!$O46,"Bez zmeny") -> 62.355 | D26: =IF(D14>0,'02'!$L46,"Bez zmeny") -> 0 | E26: =IF(E14>0,'03'!$L46,"Bez zmeny") -> 0 | F26: =IF(F14>0,'04'!$L46,"Bez zmeny") -> 0 | G26: =IF(G14>0,'05'!$L46,"Bez zmeny") -> 0 | H26: =IF(H14>0,'06'!$L46,"Bez zmeny") -> 0 | I26: =IF(I14>0,'07'!$L46,"Bez zmeny") -> 0 | J26: =IF(J14>0,'08'!$L46,"Bez zmeny") -> 0 | K26: =IF(K14>0,'09'!$L46,"Bez zmeny") -> 0 | L26: =IF(L14>0,'10'!$L46,"Bez zmeny") -> 0 | M26: =IF(M14>0,'11'!$L46,"Bez zmeny") -> 0 | N26: =IF(N14>0,'12'!$L46,"Bez zmeny") -> 0 | O26: ='12'!L7 -> 88.025 | P26: lit
B28: Tankovanie - PHM | O28: Tankovanie - PHM
B29: za Mesiac | C29: 1 | D29: 2 | E29: 3 | F29: 4 | G29: 5 | H29: 6 | I29: 7 | J29: 8 | K29: 9 | L29: 10 | M29: 11 | N29: 12 | O29: Spolu
B30: (lit) | C30: ='01'!$J$50 -> 0 | D30: ='02'!$J$50 -> 0 | E30: ='03'!$J$50 -> 55 | F30: ='04'!$J$50 -> 68 | G30: ='05'!$J$50 -> 0 | H30: ='06'!$J$50 -> 0 | I30: ='07'!$J$50 -> 0 | J30: ='08'!$J$50 -> 135.5 | K30: ='09'!$J$50 -> 0 | L30: ='10'!$J$50 -> 0 | M30: ='11'!$J$50 -> 0 | N30: ='12'!$J$50 -> 53 | O30: =SUM(C30:N30) -> 311.5 | P30: lit
B31: (€) | C31: ='01'!$K$50 -> 0 | D31: ='02'!$K$50 -> 0 | E31: ='03'!$K$50 -> 82.17 | F31: ='04'!$K$50 -> 96.83 | G31: ='05'!$K$50 -> 0 | H31: ='06'!$K$50 -> 0 | I31: ='07'!$K$50 -> 0 | J31: ='08'!$K$50 -> 126.65 | K31: ='09'!$K$50 -> 0 | L31: ='10'!$K$50 -> 0 | M31: ='11'!$K$50 -> 0 | N31: ='12'!$K$50 -> 78.92 | O31: =SUM(C31:N31) -> 384.57 | P31: €ur
E33: v Banskej Bystrici dňa; | F33: =NOW() -> 45994.678 | J33: spracoval:
B36: Vozidlo
C37: EČV: | D37: =C4 -> BB215GN | E37: ID: | F37: =C7 -> B45539 | G37: Typ: | H37: =C5 -> dodávka
G38: VIN kar. | L38: pridelené vodičovi
C39: Farba | G39: VIN mot.
C40: Výbava vozidla povinná | F40: Stav | G40: Poznámka | J40: Výbava vozidla | M40: Stav | N40: Poznámka
C41: Kniha prevádzky DP | F41: áno | J41: Náhradné koleso | M41: áno | N41: T plna guma
C42: Osvedčenie o evidencii | F42: áno | J42: Pneumatiky letné | M42: 4+1 | N42: 165/70 R14 Barum
C43: Štartovacie kľúče | F43: 2 | J43: Disky kolies leto | M43: 4 | N43: z AL zliatiny
C44: Kľúč na matice kolies | F44: áno | J44: Pneumatiky zimné | M44: 4 | N44: 165/70 R14 Barum
C45: Zdvihák | F45: áno | G45: mechanický | J45: Disky kolies zima | M45: 4 | N45: plechové
C46: Výstražný trojuholník | F46: áno
C47: Ťažné lano | F47: áno | J47: Ťažné zariadenie
C48: Lekárnička | F48: áno | G48: R2013/5 | J48: Ťažné oko | M48: áno
...

Sheet 01
A1: VÝKAZ VOZIDLA
A3: ='ROK Prev MV'!C4 -> BB215GN | E3: Mesiac: | F3: JANUÁR | H3: ='ROK Prev MV'!M2 -> 2025
A4: ='ROK Prev MV'!C5 -> dodávka | K4: Objem | L4: ='ROK Prev MV'!L5:M5 -> 90
A5: Normy | D5: STAV | E5: TACHOMETER | K5: STAV NÁDRŽ
A6: Mesto | B6: ='ROK Prev MV'!I5 -> 10.5 | E6: Začiatok | F6: Koniec | I6: Dotankovať | K6: Začiatok | L6: Koniec
A7: Vonku | B7: ='ROK Prev MV'!I4 -> 9.5 | E7: ='ROK Prev MV'!F9 -> 30109 | F7: =F43 -> 30276 | H7: =IF(I7>0," ",IF(I7<0,"Pozor",0)) | I7: =SUM(L4-L7) -> 27.645 | J7: L | K7: ='ROK Prev MV'!L8 -> 79.69 | L7: =O46 -> 62.355 | M7: L
K8: ='ROK Prev MV'!L9 -> 0 | L8: =L7*E50 -> 0 | M8: €
B9: =IF(D10>0,B10/D10*100,0) -> 88.023952 | C9: =IF(D10>0,C10/D10*100,0) -> 11.976048 | D9: %
A10: Celkom | B10: =B46 -> 147 | C10: =C46 -> 20 | D10: =D46 -> 167 | G10: priemer na 100km | I10: =IF(F7>E7,(I46/D46)*100,0) -> 10.38024
B11: Odjazd. kilometre | E11: Stav tachometra | G11: Spotreba PHM v l. | J11: Tankovanie karta | L11: Tankovanie hotovosť | O11: Zostatok
A12: Datum | B12: mesto | C12: mimo | D12: spolu | E12: začiatoč. | F12: konečný | G12: mesto | H12: mimo | I12: spolu | J12: litre | K12: € | L12: litre | M12: € | O12: litre
A13: 1 | D13: =SUM(B13:C13) -> 0 | E13: =E7 -> 30109 | F13: =SUM(E13,D13) -> 30109 | G13: =SUM((B13*B$6)/100) -> 0 | H13: =SUM((C13*B$7)/100) -> 0 | I13: =SUM(G13:H13) -> 0 | N13: 1 | O13: =(K7-I13)+J13+L13 -> 79.69
A14: 2 | D14: =SUM(B14:C14) -> 0 | E14: =F13 -> 30109 | F14: =SUM(E14,D14) -> 30109 | G14: =SUM((B14*B$6)/100) -> 0 | H14: =SUM((C14*B$7)/100) -> 0 | I14: =SUM(G14:H14) -> 0 | N14: 2 | O14: =(O13-I14)+J14+L14 -> 79.69
A15: 3 | D15: =SUM(B15:C15) -> 0 | E15: =F14 -> 30109 | F15: =SUM(E15,D15) -> 30109 | G15: =SUM((B15*B$6)/100) -> 0 | H15: =SUM((C15*B$7)/100) -> 0 | I15: =SUM(G15:H15) -> 0 | N15: 3 | O15: =(O14-I15)+J15+L15 -> 79.69
A16: 4 | D16: =SUM(B16:C16) -> 0 | E16: =F15 -> 30109 | F16: =SUM(E16,D16) -> 30109 | G16: =SUM((B16*B$6)/100) -> 0 | H16: =SUM((C16*B$7)/100) -> 0 | I16: =SUM(G16:H16) -> 0 | N16: 4 | O16: =(O15-I16)+J16+L16 -> 79.69
A17: 5 | D17: =SUM(B17:C17) -> 0 | E17: =F16 -> 30109 | F17: =SUM(E17,D17) -> 30109 | G17: =SUM((B17*B$6)/100) -> 0 | H17: =SUM((C17*B$7)/100) -> 0 | I17: =SUM(G17:H17) -> 0 | N17: 5 | O17: =(O16-I17)+J17+L17 -> 79.69
A18: 6 | D18: =SUM(B18:C18) -> 0 | E18: =F17 -> 30109 | F18: =SUM(E18,D18) -> 30109 | G18: =SUM((B18*B$6)/100) -> 0 | H18: =SUM((C18*B$7)/100) -> 0 | I18: =SUM(G18:H18) -> 0 | N18: 6 | O18: =(O17-I18)+J18+L18 -> 79.69
A19: 7 | B19: 14 | D19: =SUM(B19:C19) -> 14 | E19: =F18 -> 30109 | F19: =SUM(E19,D19) -> 30123 | G19: =SUM((B19*B$6)/100) -> 1.47 | H19: =SUM((C19*B$7)/100) -> 0 | I19: =SUM(G19:H19) -> 1.47 | N19: 7 | O19: =(O18-I19)+J19+L19 -> 78.22
A20: 8 | B20: 29 | D20: =SUM(B20:C20) -> 29 | E20: =F19 -> 30123 | F20: =SUM(E20,D20) -> 30152 | G20: =SUM((B20*B$6)/100) -> 3.045 | H20: =SUM((C20*B$7)/100) -> 0 | I20: =SUM(G20:H20) -> 3.045 | N20: 8 | O20: =(O19-I20)+J20+L20 -> 75.175
A21: 9 | D21: =SUM(B21:C21) -> 0 | E21: =F20 -> 30152 | F21: =SUM(E21,D21) -> 30152 | G21: =SUM((B21*B$6)/100) -> 0 | H21: =SUM((C21*B$7)/100) -> 0 | I21: =SUM(G21:H21) -> 0 | N21: 9 | O21: =(O20-I21)+J21+L21 -> 75.175
A22: 10 | D22: =SUM(B22:C22) -> 0 | E22: =F21 -> 30152 | F22: =SUM(E22,D22) -> 30152 | G22: =SUM((B22*B$6)/100) -> 0 | H22: =SUM((C22*B$7)/100) -> 0 | I22: =SUM(G22:H22) -> 0 | N22: 10 | O22: =(O21-I22)+J22+L22 -> 75.175
A23: 11 | D23: =SUM(B23:C23) -> 0 | E23: =F22 -> 30152 | F23: =SUM(E23,D23) -> 30152 | G23: =SUM((B23*B$6)/100) -> 0 | H23: =SUM((C23*B$7)/100) -> 0 | I23: =SUM(G23:H23) -> 0 | N23: 11 | O23: =(O22-I23)+J23+L23 -> 75.175
A24: 12 | D24: =SUM(B24:C24) -> 0 | E24: =F23 -> 30152 | F24: =SUM(E24,D24) -> 30152 | G24: =SUM((B24*B$6)/100) -> 0 | H24: =SUM((C24*B$7)/100) -> 0 | I24: =SUM(G24:H24) -> 0 | N24: 12 | O24: =(O23-I24)+J24+L24 -> 75.175
A25: 13 | D25: =SUM(B25:C25) -> 0 | E25: =F24 -> 30152 | F25: =SUM(E25,D25) -> 30152 | G25: =SUM((B25*B$6)/100) -> 0 | H25: =SUM((C25*B$7)/100) -> 0 | I25: =SUM(G25:H25) -> 0 | N25: 13 | O25: =(O24-I25)+J25+L25 -> 75.175
A26: 14 | D26: =SUM(B26:C26) -> 0 | E26: =F25 -> 30152 | F26: =SUM(E26,D26) -> 30152 | G26: =SUM((B26*B$6)/100) -> 0 | H26: =SUM((C26*B$7)/100) -> 0 | I26: =SUM(G26:H26) -> 0 | N26: 14 | O26: =(O25-I26)+J26+L26 -> 75.175
A27: 15 | D27: =SUM(B27:C27) -> 0 | E27: =F26 -> 30152 | F27: =SUM(E27,D27) -> 30152 | G27: =SUM((B27*B$6)/100) -> 0 | H27: =SUM((C27*B$7)/100) -> 0 | I27: =SUM(G27:H27) -> 0 | N27: 15 | O27: =(O26-I27)+J27+L27 -> 75.175
A28: 16 | D28: =SUM(B28:C28) -> 0 | E28: =F27 -> 30152 | F28: =SUM(E28,D28) -> 30152 | G28: =SUM((B28*B$6)/100) -> 0 | H28: =SUM((C28*B$7)/100) -> 0 | I28: =SUM(G28:H28) -> 0 | N28: 16 | O28: =(O27-I28)+J28+L28 -> 75.175
A29: 17 | B29: 6 | D29: =SUM(B29:C29) -> 6 | E29: =F28 -> 30152 | F29: =SUM(E29,D29) -> 30158 | G29: =SUM((B29*B$6)/100) -> 0.63 | H29: =SUM((C29*B$7)/100) -> 0 | I29: =SUM(G29:H29) -> 0.63 | N29: 17 | O29: =(O28-I29)+J29+L29 -> 74.545
A30: 18 | D30: =SUM(B30:C30) -> 0 | E30: =F29 -> 30158 | F30: =SUM(E30,D30) -> 30158 | G30: =SUM((B30*B$6)/100) -> 0 | H30: =SUM((C30*B$7)/100) -> 0 | I30: =SUM(G30:H30) -> 0 | N30: 18 | O30: =(O29-I30)+J30+L30 -> 74.545
A31: 19 | D31: =SUM(B31:C31) -> 0 | E31: =F30 -> 30158 | F31: =SUM(E31,D31) -> 30158 | G31: =SUM((B31*B$6)/100) -> 0 | H31: =SUM((C31*B$7)/100) -> 0 | I31: =SUM(G31:H31) -> 0 | N31: 19 | O31: =(O30-I31)+J31+L31 -> 74.545
A32: 20 | D32: =SUM(B32:C32) -> 0 | E32: =F31 -> 30158 | F32: =SUM(E32,D32) -> 30158 | G32: =SUM((B32*B$6)/100) -> 0 | H32: =SUM((C32*B$7)/100) -> 0 | I32: =SUM(G32:H32) -> 0 | N32: 20 | O32: =(O31-I32)+J32+L32 -> 74.545
A33: 21 | D33: =SUM(B33:C33) -> 0 | E33: =F32 -> 30158 | F33: =SUM(E33,D33) -> 30158 | G33: =SUM((B33*B$6)/100) -> 0 | H33: =SUM((C33*B$7)/100) -> 0 | I33: =SUM(G33:H33) -> 0 | N33: 21 | O33: =(O32-I33)+J33+L33 -> 74.545
A34: 22 | D34: =SUM(B34:C34) -> 0 | E34: =F33 -> 30158 | F34: =SUM(E34,D34) -> 30158 | G34: =SUM((B34*B$6)/100) -> 0 | H34: =SUM((C34*B$7)/100) -> 0 | I34: =SUM(G34:H34) -> 0 | N34: 22 | O34: =(O33-I34)+J34+L34 -> 74.545
A35: 23 | B35: 42 | D35: =SUM(B35:C35) -> 42 | E35: =F34 -> 30158 | F35: =SUM(E35,D35) -> 30200 | G35: =SUM((B35*B$6)/100) -> 4.41 | H35: =SUM((C35*B$7)/100) -> 0 | I35: =SUM(G35:H35) -> 4.41 | N35: 23 | O35: =(O34-I35)+J35+L35 -> 70.135
A36: 24 | D36: =SUM(B36:C36) -> 0 | E36: =F35 -> 30200 | F36: =SUM(E36,D36) -> 30200 | G36: =SUM((B36*B$6)/100) -> 0 | H36: =SUM((C36*B$7)/100) -> 0 | I36: =SUM(G36:H36) -> 0 | N36: 24 | O36: =(O35-I36)+J36+L36 -> 70.135
A37: 25 | D37: =SUM(B37:C37) -> 0 | E37: =F36 -> 30200 | F37: =SUM(E37,D37) -> 30200 | G37: =SUM((B37*B$6)/100) -> 0 | H37: =SUM((C37*B$7)/100) -> 0 | I37: =SUM(G37:H37) -> 0 | N37: 25 | O37: =(O36-I37)+J37+L37 -> 70.135
A38: 26 | D38: =SUM(B38:C38) -> 0 | E38: =F37 -> 30200 | F38: =SUM(E38,D38) -> 30200 | G38: =SUM((B38*B$6)/100) -> 0 | H38: =SUM((C38*B$7)/100) -> 0 | I38: =SUM(G38:H38) -> 0 | N38: 26 | O38: =(O37-I38)+J38+L38 -> 70.135
A39: 27 | D39: =SUM(B39:C39) -> 0 | E39: =F38 -> 30200 | F39: =SUM(E39,D39) -> 30200 | G39: =SUM((B39*B$6)/100) -> 0 | H39: =SUM((C39*B$7)/100) -> 0 | I39: =SUM(G39:H39) -> 0 | N39: 27 | O39: =(O38-I39)+J39+L39 -> 70.135
A40: 28 | B40: 33 | C40: 20 | D40: =SUM(B40:C40) -> 53 | E40: =F39 -> 30200 | F40: =SUM(E40,D40) -> 30253 | G40: =SUM((B40*B$6)/100) -> 3.465 | H40: =SUM((C40*B$7)/100) -> 1.9 | I40: =SUM(G40:H40) -> 5.365 | N40: 28 | O40: =(O39-I40)+J40+L40 -> 64.77
A41: 29 | D41: =SUM(B41:C41) -> 0 | E41: =F40 -> 30253 | F41: =SUM(E41,D41) -> 30253 | G41: =SUM((B41*B$6)/100) -> 0 | H41: =SUM((C41*B$7)/100) -> 0 | I41: =SUM(G41:H41) -> 0 | N41: 29 | O41: =(O40-I41)+J41+L41 -> 64.77
...

Sheet 02
A1: VÝKAZ VOZIDLA
A3: ='ROK Prev MV'!C4 -> BB215GN | E3: Mesiac: | F3: FEBRUAR | H3: ='ROK Prev MV'!M2 -> 2025
A4: ='ROK Prev MV'!C5 -> dodávka | K4: Objem | L4: ='ROK Prev MV'!L5:M5 -> 90
A5: Normy | D5: STAV | E5: TACHOMETER | K5: STAV NÁDRŽ
A6: Mesto | B6: ='ROK Prev MV'!I5 -> 10.5 | E6: Začiatok | F6: Koniec | I6: Dotankovať | K6: Začiatok | L6: Koniec
A7: Vonku | B7: ='ROK Prev MV'!I4 -> 9.5 | E7: ='01'!F7 -> 30276 | F7: =F43 -> 30427 | H7: =IF(I7>0," ",IF(I7<0,"Pozor",0)) | I7: =SUM(L4-L7) -> 43 | J7: L | K7: ='01'!L7 -> 62.355 | L7: =O46 -> 47 | M7: L
K8: ='01'!L8 -> 0 | L8: =L7*E50 -> 0 | M8: €
B9: =IF(D10>0,B10/D10*100,0) -> 66.887417 | C9: =IF(D10>0,C10/D10*100,0) -> 33.112583 | D9: %
A10: Celkom | B10: =B46 -> 101 | C10: =C46 -> 50 | D10: =D46 -> 151 | G10: priemer na 100km | I10: =IF(F7>E7,(I46/D46)*100,0) -> 10.168874
B11: Odjazd. kilometre | E11: Stav tachometra | G11: Spotreba PHM v l. | J11: Tankovanie karta | L11: Tankovanie hotovosť | O11: Zostatok
A12: Datum | B12: mesto | C12: mimo | D12: spolu | E12: začiatoč. | F12: konečný | G12: mesto | H12: mimo | I12: spolu | J12: litre | K12: € | L12: litre | M12: € | O12: litre
A13: 1 | D13: =SUM(B13:C13) -> 0 | E13: =E7 -> 30276 | F13: =SUM(E13,D13) -> 30276 | G13: =SUM((B13*B$6)/100) -> 0 | H13: =SUM((C13*B$7)/100) -> 0 | I13: =SUM(G13:H13) -> 0 | N13: 1 | O13: =(K7-I13)+J13+L13 -> 62.355
A14: 2 | D14: =SUM(B14:C14) -> 0 | E14: =F13 -> 30276 | F14: =SUM(E14,D14) -> 30276 | G14: =SUM((B14*B$6)/100) -> 0 | H14: =SUM((C14*B$7)/100) -> 0 | I14: =SUM(G14:H14) -> 0 | N14: 2 | O14: =(O13-I14)+J14+L14 -> 62.355
A15: 3 | D15: =SUM(B15:C15) -> 0 | E15: =F14 -> 30276 | F15: =SUM(E15,D15) -> 30276 | G15: =SUM((B15*B$6)/100) -> 0 | H15: =SUM((C15*B$7)/100) -> 0 | I15: =SUM(G15:H15) -> 0 | N15: 3 | O15: =(O14-I15)+J15+L15 -> 62.355
A16: 4 | B16: 33 | C16: 30 | D16: =SUM(B16:C16) -> 63 | E16: =F15 -> 30276 | F16: =SUM(E16,D16) -> 30339 | G16: =SUM((B16*B$6)/100) -> 3.465 | H16: =SUM((C16*B$7)/100) -> 2.85 | I16: =SUM(G16:H16) -> 6.315 | N16: 4 | O16: =(O15-I16)+J16+L16 -> 56.04
A17: 5 | D17: =SUM(B17:C17) -> 0 | E17: =F16 -> 30339 | F17: =SUM(E17,D17) -> 30339 | G17: =SUM((B17*B$6)/100) -> 0 | H17: =SUM((C17*B$7)/100) -> 0 | I17: =SUM(G17:H17) -> 0 | N17: 5 | O17: =(O16-I17)+J17+L17 -> 56.04
A18: 6 | D18: =SUM(B18:C18) -> 0 | E18: =F17 -> 30339 | F18: =SUM(E18,D18) -> 30339 | G18: =SUM((B18*B$6)/100) -> 0 | H18: =SUM((C18*B$7)/100) -> 0 | I18: =SUM(G18:H18) -> 0 | N18: 6 | O18: =(O17-I18)+J18+L18 -> 56.04
A19: 7 | D19: =SUM(B19:C19) -> 0 | E19: =F18 -> 30339 | F19: =SUM(E19,D19) -> 30339 | G19: =SUM((B19*B$6)/100) -> 0 | H19: =SUM((C19*B$7)/100) -> 0 | I19: =SUM(G19:H19) -> 0 | N19: 7 | O19: =(O18-I19)+J19+L19 -> 56.04
A20: 8 | D20: =SUM(B20:C20) -> 0 | E20: =F19 -> 30339 | F20: =SUM(E20,D20) -> 30339 | G20: =SUM((B20*B$6)/100) -> 0 | H20: =SUM((C20*B$7)/100) -> 0 | I20: =SUM(G20:H20) -> 0 | N20: 8 | O20: =(O19-I20)+J20+L20 -> 56.04
A21: 9 | D21: =SUM(B21:C21) -> 0 | E21: =F20 -> 30339 | F21: =SUM(E21,D21) -> 30339 | G21: =SUM((B21*B$6)/100) -> 0 | H21: =SUM((C21*B$7)/100) -> 0 | I21: =SUM(G21:H21) -> 0 | N21: 9 | O21: =(O20-I21)+J21+L21 -> 56.04
A22: 10 | D22: =SUM(B22:C22) -> 0 | E22: =F21 -> 30339 | F22: =SUM(E22,D22) -> 30339 | G22: =SUM((B22*B$6)/100) -> 0 | H22: =SUM((C22*B$7)/100) -> 0 | I22: =SUM(G22:H22) -> 0 | N22: 10 | O22: =(O21-I22)+J22+L22 -> 56.04
A23: 11 | D23: =SUM(B23:C23) -> 0 | E23: =F22 -> 30339 | F23: =SUM(E23,D23) -> 30339 | G23: =SUM((B23*B$6)/100) -> 0 | H23: =SUM((C23*B$7)/100) -> 0 | I23: =SUM(G23:H23) -> 0 | N23: 11 | O23: =(O22-I23)+J23+L23 -> 56.04
A24: 12 | D24: =SUM(B24:C24) -> 0 | E24: =F23 -> 30339 | F24: =SUM(E24,D24) -> 30339 | G24: =SUM((B24*B$6)/100) -> 0 | H24: =SUM((C24*B$7)/100) -> 0 | I24: =SUM(G24:H24) -> 0 | N24: 12 | O24: =(O23-I24)+J24+L24 -> 56.04
A25: 13 | D25: =SUM(B25:C25) -> 0 | E25: =F24 -> 30339 | F25: =SUM(E25,D25) -> 30339 | G25: =SUM((B25*B$6)/100) -> 0 | H25: =SUM((C25*B$7)/100) -> 0 | I25: =SUM(G25:H25) -> 0 | N25: 13 | O25: =(O24-I25)+J25+L25 -> 56.04
A26: 14 | D26: =SUM(B26:C26) -> 0 | E26: =F25 -> 30339 | F26: =SUM(E26,D26) -> 30339 | G26: =SUM((B26*B$6)/100) -> 0 | H26: =SUM((C26*B$7)/100) -> 0 | I26: =SUM(G26:H26) -> 0 | N26: 14 | O26: =(O25-I26)+J26+L26 -> 56.04
A27: 15 | D27: =SUM(B27:C27) -> 0 | E27: =F26 -> 30339 | F27: =SUM(E27,D27) -> 30339 | G27: =SUM((B27*B$6)/100) -> 0 | H27: =SUM((C27*B$7)/100) -> 0 | I27: =SUM(G27:H27) -> 0 | N27: 15 | O27: =(O26-I27)+J27+L27 -> 56.04
A28: 16 | D28: =SUM(B28:C28) -> 0 | E28: =F27 -> 30339 | F28: =SUM(E28,D28) -> 30339 | G28: =SUM((B28*B$6)/100) -> 0 | H28: =SUM((C28*B$7)/100) -> 0 | I28: =SUM(G28:H28) -> 0 | N28: 16 | O28: =(O27-I28)+J28+L28 -> 56.04
... A35: 23 | D35: =SUM(B35:C35) -> 0 | E35: =F34 -> 30339 | F35: =SUM(E35,D35) -> 30339 | G35: =SUM((B35*B$6)/100) -> 0 | H35: =SUM((C35*B$7)/100) -> 0 | I35: =SUM(G35:H35) -> 0 | N35: 23 | O35: =(O34-I35)+J35+L35 -> 56.04
A36: 24 | B36: 19 | D36: =SUM(B36:C36) -> 19 | E36: =F35 -> 30339 | F36: =SUM(E36,D36) -> 30358 | G36: =SUM((B36*B$6)/100) -> 1.995 | H36: =SUM((C36*B$7)/100) -> 0 | I36: =SUM(G36:H36) -> 1.995 | N36: 24 | O36: =(O35-I36)+J36+L36 -> 54.045
A37: 25 | B37: 25 | C37: 20 | D37: =SUM(B37:C37) -> 45 | E37: =F36 -> 30358 | F37: =SUM(E37,D37) -> 30403 | G37: =SUM((B37*B$6)/100) -> 2.625 | H37: =SUM((C37*B$7)/100) -> 1.9 | I37: =SUM(G37:H37) -> 4.525 | N37: 25 | O37: =(O36-I37)+J37+L37 -> 49.52
A38: 26 | D38: =SUM(B38:C38) -> 0 | E38: =F37 -> 30403 | F38: =SUM(E38,D38) -> 30403 | G38: =SUM((B38*B$6)/100) -> 0 | H38: =SUM((C38*B$7)/100) -> 0 | I38: =SUM(G38:H38) -> 0 | N38: 26 | O38: =(O37-I38)+J38+L38 -> 49.52
A39: 27 | B39: 24 | D39: =SUM(B39:C39) -> 24 | E39: =F38 -> 30403 | F39: =SUM(E39,D39) -> 30427 | G39: =SUM((B39*B$6)/100) -> 2.52 | H39: =SUM((C39*B$7)/100) -> 0 | I39: =SUM(G39:H39) -> 2.52 | N39: 27 | O39: =(O38-I39)+J39+L39 -> 47
A40: 28 | D40: =SUM(B40:C40) -> 0 | E40: =F39 -> 30427 | F40: =SUM(E40,D40) -> 30427 | G40: =SUM((B40*B$6)/100) -> 0 | H40: =SUM((C40*B$7)/100) -> 0 | I40: =SUM(G40:H40) -> 0 | N40: 28 | O40: =(O39-I40)+J40+L40 -> 47
A41: 29 | D41: =SUM(B41:C41) -> 0 | E41: =F40 -> 30427 | F41: =SUM(E41,D41) -> 30427 | G41: =SUM((B41*B$6)/100) -> 0 | H41: =SUM((C41*B$7)/100) -> 0 | I41: =SUM(G41:H41) -> 0 | N41: 29 | O41: =(O40-I41)+J41+L41 -> 47
A42: 30 | D42: =SUM(B42:C42) -> 0 | E42: =F41 -> 30427 | F42: =SUM(E42,D42) -> 30427 | G42: =SUM((B42*B$6)/100) -> 0 | H42: =SUM((C42*B$7)/100) -> 0 | I42: =SUM(G42:H42) -> 0 | N42: 30 | O42: =(O41-I42)+J42+L42 -> 47
A43: 31 | D43: =SUM(B43:C43) -> 0 | E43: =F42 -> 30427 | F43: =SUM(E43,D43) -> 30427 | G43: =SUM((B43*B$6)/100) -> 0 | H43: =SUM((C43*B$7)/100) -> 0 | I43: =SUM(G43:H43) -> 0 | N43: 31 | O43: =(O42-I43)+J43+L43 -> 47
B44: Odjazd. kilometre | E44: Stav tachometra | G44: Spotreba PHM v l. | J44: Tankovanie karta | L44: Tankovanie hotovosť | O44: Zostatok
A45: Datum | B45: mesto | C45: mimo | D45: spolu | E45: začiatoč. | F45: konečný | G45: mesto | H45: mimo | I45: spolu | J45: litre | K45: € | L45: litre | M45: € | O45: litre
B46: =SUM(B13:B43) -> 101 | C46: =SUM(C13:C43) -> 50 | D46: =SUM(D13:D43) -> 151 | E46: =E7 -> 30276 | F46: =F43 -> 30427 | G46: =SUM(G13:G43) -> 10.605 | H46: =SUM(H13:H43) -> 4.75 | I46: =SUM(I13:I43) -> 15.355 | J46: =SUM(J13:J43) -> 0 | K46: =SUM(K13:K43) -> 0 | L46: =SUM(L13:L43) -> 0 | M46: =SUM(M13:M43) -> 0 | O46: =O43 -> 47
C48: Palivo | E48: Priemerná cena | G48: Spotreba PHM v €. | J48: Tankovanie celkom
...

Sheet 03
A1: VÝKAZ VOZIDLA
A3: ='ROK Prev MV'!C4 -> BB215GN | E3: Mesiac: | F3: MAREC | H3: ='ROK Prev MV'!M2 -> 2025
A4: ='ROK Prev MV'!C5 -> dodávka | K4: Objem | L4: ='ROK Prev MV'!L5:M5 -> 90
A5: Normy | D5: STAV | E5: TACHOMETER | K5: STAV NÁDRŽ
A6: Mesto | B6: ='ROK Prev MV'!I5 -> 10.5 | E6: Začiatok | F6: Koniec | I6: Dotankovať | K6: Začiatok | L6: Koniec
A7: Vonku | B7: ='ROK Prev MV'!I4 -> 9.5 | E7: ='02'!F7 -> 30427 | F7: =F43 -> 30575 | H7: =IF(I7>0," ",IF(I7<0,"Pozor",0)) | I7: =SUM(L4-L7) -> 2.89 | J7: L | K7: ='02'!L7 -> 47 | L7: =O46 -> 87.11 | M7: L
K8: ='02'!L8 -> 0 | L8: =L7*E50 -> 70.21066 | M8: €
B9: =IF(D10>0,B10/D10*100,0) -> 56.081081 | C9: =IF(D10>0,C10/D10*100,0) -> 43.918919 | D9: %
A10: Celkom | B10: =B46 -> 83 | C10: =C46 -> 65 | D10: =D46 -> 148 | G10: priemer na 100km | I10: =IF(F7>E7,(I46/D46)*100,0) -> 10.060811
B11: Odjazd. kilometre | E11: Stav tachometra | G11: Spotreba PHM v l. | J11: Tankovanie karta | L11: Tankovanie hotovosť | O11: Zostatok
A12: Datum | B12: mesto | C12: mimo | D12: spolu | E12: začiatoč. | F12: konečný | G12: mesto | H12: mimo | I12: spolu | J12: litre | K12: € | L12: litre | M12: € | O12: litre
A13: 1 | D13: =SUM(B13:C13) -> 0 | E13: =E7 -> 30427 | F13: =SUM(E13,D13) -> 30427 | G13: =SUM((B13*B$6)/100) -> 0 | H13: =SUM((C13*B$7)/100) -> 0 | I13: =SUM(G13:H13) -> 0 | N13: 1 | O13: =(K7-I13)+J13+L13 -> 47
A14: 2 | D14: =SUM(B14:C14) -> 0 | E14: =F13 -> 30427 | F14: =SUM(E14,D14) -> 30427 | G14: =SUM((B14*B$6)/100) -> 0 | H14: =SUM((C14*B$7)/100) -> 0 | I14: =SUM(G14:H14) -> 0 | N14: 2 | O14: =(O13-I14)+J14+L14 -> 47
A15: 3 | D15: =SUM(B15:C15) -> 0 | E15: =F14 -> 30427 | F15: =SUM(E15,D15) -> 30427 | G15: =SUM((B15*B$6)/100) -> 0 | H15: =SUM((C15*B$7)/100) -> 0 | I15: =SUM(G15:H15) -> 0 | N15: 3 | O15: =(O14-I15)+J15+L15 -> 47
A16: 4 | D16: =SUM(B16:C16) -> 0 | E16: =F15 -> 30427 | F16: =SUM(E16,D16) -> 30427 | G16: =SUM((B16*B$6)/100) -> 0 | H16: =SUM((C16*B$7)/100) -> 0 | I16: =SUM(G16:H16) -> 0 | N16: 4 | O16: =(O15-I16)+J16+L16 -> 47
A17: 5 | D17: =SUM(B17:C17) -> 0 | E17: =F16 -> 30427 | F17: =SUM(E17,D17) -> 30427 | G17: =SUM((B17*B$6)/100) -> 0 | H17: =SUM((C17*B$7)/100) -> 0 | I17: =SUM(G17:H17) -> 0 | N17: 5 | O17: =(O16-I17)+J17+L17 -> 47
A18: 6 | D18: =SUM(B18:C18) -> 0 | E18: =F17 -> 30427 | F18: =SUM(E18,D18) -> 30427 | G18: =SUM((B18*B$6)/100) -> 0 | H18: =SUM((C18*B$7)/100) -> 0 | I18: =SUM(G18:H18) -> 0 | N18: 6 | O18: =(O17-I18)+J18+L18 -> 47
A19: 7 | D19: =SUM(B19:C19) -> 0 | E19: =F18 -> 30427 | F19: =SUM(E19,D19) -> 30427 | G19: =SUM((B19*B$6)/100) -> 0 | H19: =SUM((C19*B$7)/100) -> 0 | I19: =SUM(G19:H19) -> 0 | N19: 7 | O19: =(O18-I19)+J19+L19 -> 47
A20: 8 | D20: =SUM(B20:C20) -> 0 | E20: =F19 -> 30427 | F20: =SUM(E20,D20) -> 30427 | G20: =SUM((B20*B$6)/100) -> 0 | H20: =SUM((C20*B$7)/100) -> 0 | I20: =SUM(G20:H20) -> 0 | N20: 8 | O20: =(O19-I20)+J20+L20 -> 47
A21: 9 | D21: =SUM(B21:C21) -> 0 | E21: =F20 -> 30427 | F21: =SUM(E21,D21) -> 30427 | G21: =SUM((B21*B$6)/100) -> 0 | H21: =SUM((C21*B$7)/100) -> 0 | I21: =SUM(G21:H21) -> 0 | N21: 9 | O21: =(O20-I21)+J21+L21 -> 47
A22: 10 | D22: =SUM(B22:C22) -> 0 | E22: =F21 -> 30427 | F22: =SUM(E22,D22) -> 30427 | G22: =SUM((B22*B$6)/100) -> 0 | H22: =SUM((C22*B$7)/100) -> 0 | I22: =SUM(G22:H22) -> 0 | N22: 10 | O22: =(O21-I22)+J22+L22 -> 47
A23: 11 | D23: =SUM(B23:C23) -> 0 | E23: =F22 -> 30427 | F23: =SUM(E23,D23) -> 30427 | G23: =SUM((B23*B$6)/100) -> 0 | H23: =SUM((C23*B$7)/100) -> 0 | I23: =SUM(G23:H23) -> 0 | N23: 11 | O23: =(O22-I23)+J23+L23 -> 47
A24: 12 | D24: =SUM(B24:C24) -> 0 | E24: =F23 -> 30427 | F24: =SUM(E24,D24) -> 30427 | G24: =SUM((B24*B$6)/100) -> 0 | H24: =SUM((C24*B$7)/100) -> 0 | I24: =SUM(G24:H24) -> 0 | N24: 12 | O24: =(O23-I24)+J24+L24 -> 47
A25: 13 | D25: =SUM(B25:C25) -> 0 | E25: =F24 -> 30427 | F25: =SUM(E25,D25) -> 30427 | G25: =SUM((B25*B$6)/100) -> 0 | H25: =SUM((C25*B$7)/100) -> 0 | I25: =SUM(G25:H25) -> 0 | N25: 13 | O25: =(O24-I25)+J25+L25 -> 47
... A29: 17 | D29: =SUM(B29:C29) -> 0 | E29: =F28 -> 30427 | F29: =SUM(E29,D29) -> 30427 | G29: =SUM((B29*B$6)/100) -> 0 | H29: =SUM((C29*B$7)/100) -> 0 | I29: =SUM(G29:H29) -> 0 | N29: 17 | O29: =(O28-I29)+J29+L29 -> 47
A30: 18 | B30: 36 | D30: =SUM(B30:C30) -> 36 | E30: =F29 -> 30427 | F30: =SUM(E30,D30) -> 30463 | G30: =SUM((B30*B$6)/100) -> 3.78 | H30: =SUM((C30*B$7)/100) -> 0 | I30: =SUM(G30:H30) -> 3.78 | N30: 18 | O30: =(O29-I30)+J30+L30 -> 43.22
A31: 19 | B31: 27 | C31: 40 | D31: =SUM(B31:C31) -> 67 | E31: =F30 -> 30463 | F31: =SUM(E31,D31) -> 30530 | G31: =SUM((B31*B$6)/100) -> 2.835 | H31: =SUM((C31*B$7)/100) -> 3.8 | I31: =SUM(G31:H31) -> 6.635 | N31: 19 | O31: =(O30-I31)+J31+L31 -> 36.585
A32: 20 | D32: =SUM(B32:C32) -> 0 | E32: =F31 -> 30530 | F32: =SUM(E32,D32) -> 30530 | G32: =SUM((B32*B$6)/100) -> 0 | H32: =SUM((C32*B$7)/100) -> 0 | I32: =SUM(G32:H32) -> 0 | N32: 20 | O32: =(O31-I32)+J32+L32 -> 36.585
A33: 21 | D33: =SUM(B33:C33) -> 0 | E33: =F32 -> 30530 | F33: =SUM(E33,D33) -> 30530 | G33: =SUM((B33*B$6)/100) -> 0 | H33: =SUM((C33*B$7)/100) -> 0 | I33: =SUM(G33:H33) -> 0 | N33: 21 | O33: =(O32-I33)+J33+L33 -> 36.585
A34: 22 | D34: =SUM(B34:C34) -> 0 | E34: =F33 -> 30530 | F34: =SUM(E34,D34) -> 30530 | G34: =SUM((B34*B$6)/100) -> 0 | H34: =SUM((C34*B$7)/100) -> 0 | I34: =SUM(G34:H34) -> 0 | N34: 22 | O34: =(O33-I34)+J34+L34 -> 36.585
A35: 23 | D35: =SUM(B35:C35) -> 0 | E35: =F34 -> 30530 | F35: =SUM(E35,D35) -> 30530 | G35: =SUM((B35*B$6)/100) -> 0 | H35: =SUM((C35*B$7)/100) -> 0 | I35: =SUM(G35:H35) -> 0 | N35: 23 | O35: =(O34-I35)+J35+L35 -> 36.585
A36: 24 | D36: =SUM(B36:C36) -> 0 | E36: =F35 -> 30530 | F36: =SUM(E36,D36) -> 30530 | G36: =SUM((B36*B$6)/100) -> 0 | H36: =SUM((C36*B$7)/100) -> 0 | I36: =SUM(G36:H36) -> 0 | N36: 24 | O36: =(O35-I36)+J36+L36 -> 36.585
A37: 25 | D37: =SUM(B37:C37) -> 0 | E37: =F36 -> 30530 | F37: =SUM(E37,D37) -> 30530 | G37: =SUM((B37*B$6)/100) -> 0 | H37: =SUM((C37*B$7)/100) -> 0 | I37: =SUM(G37:H37) -> 0 | N37: 25 | O37: =(O36-I37)+J37+L37 -> 36.585
A38: 26 | D38: =SUM(B38:C38) -> 0 | E38: =F37 -> 30530 | F38: =SUM(E38,D38) -> 30530 | G38: =SUM((B38*B$6)/100) -> 0 | H38: =SUM((C38*B$7)/100) -> 0 | I38: =SUM(G38:H38) -> 0 | N38: 26 | O38: =(O37-I38)+J38+L38 -> 36.585
A39: 27 | D39: =SUM(B39:C39) -> 0 | E39: =F38 -> 30530 | F39: =SUM(E39,D39) -> 30530 | G39: =SUM((B39*B$6)/100) -> 0 | H39: =SUM((C39*B$7)/100) -> 0 | I39: =SUM(G39:H39) -> 0 | N39: 27 | O39: =(O38-I39)+J39+L39 -> 36.585
A40: 28 | B40: 20 | C40: 25 | D40: =SUM(B40:C40) -> 45 | E40: =F39 -> 30530 | F40: =SUM(E40,D40) -> 30575 | G40: =SUM((B40*B$6)/100) -> 2.1 | H40: =SUM((C40*B$7)/100) -> 2.375 | I40: =SUM(G40:H40) -> 4.475 | J40: 55 | K40: 82.17 | N40: 28 | O40: =(O39-I40)+J40+L40 -> 87.11
A41: 29 | D41: =SUM(B41:C41) -> 0 | E41: =F40 -> 30575 | F41: =SUM(E41,D41) -> 30575 | G41: =SUM((B41*B$6)/100) -> 0 | H41: =SUM((C41*B$7)/100) -> 0 | I41: =SUM(G41:H41) -> 0 | N41: 29 | O41: =(O40-I41)+J41+L41 -> 87.11
A42: 30 | D42: =SUM(B42:C42) -> 0 | E42: =F41 -> 30575 | F42: =SUM(E42,D42) -> 30575 | G42: =SUM((B42*B$6)/100) -> 0 | H42: =SUM((C42*B$7)/100) -> 0 | I42: =SUM(G42:H42) -> 0 | N42: 30 | O42: =(O41-I42)+J42+L42 -> 87.11
A43: 31 | D43: =SUM(B43:C43) -> 0 | E43: =F42 -> 30575 | F43: =SUM(E43,D43) -> 30575 | G43: =SUM((B43*B$6)/100) -> 0 | H43: =SUM((C43*B$7)/100) -> 0 | I43: =SUM(G43:H43) -> 0 | N43: 31 | O43: =(O42-I43)+J43+L43 -> 87.11
B44: Odjazd. kilometre | E44: Stav tachometra | G44: Spotreba PHM v l. | J44: Tankovanie karta | L44: Tankovanie hotovosť | O44: Zostatok
...

Sheet 04
A1: VÝKAZ VOZIDLA
A3: ='ROK Prev MV'!C4 -> BB215GN | E3: Mesiac: | F3: APRIL | H3: ='ROK Prev MV'!M2 -> 2025
A4: ='ROK Prev MV'!C5 -> dodávka | K4: Objem | L4: ='ROK Prev MV'!L5:M5 -> 90
A5: Normy | D5: STAV | E5: TACHOMETER | K5: STAV NÁDRŽ
A6: Mesto | B6: ='ROK Prev MV'!I5 -> 10.5 | E6: Začiatok | F6: Koniec | I6: Dotankovať | K6: Začiatok | L6: Koniec
A7: Vonku | B7: ='ROK Prev MV'!I4 -> 9.5 | E7: ='03'!F7 -> 30575 | F7: =F43 -> 31259 | H7: =IF(I7>0," ",IF(I7<0,"Pozor",0)) | I7: =SUM(L4-L7) -> 1.71 | J7: L | K7: ='03'!L7 -> 87.11 | L7: =O46 -> 88.29 | M7: L
K8: ='03'!L8 -> 70.21066 | L8: =L7*E50 -> 95.08833 | M8: €
B9: =IF(D10>0,B10/D10*100,0) -> 26.900585 | C9: =IF(D10>0,C10/D10*100,0) -> 73.099415 | D9: %
A10: Celkom | B10: =B46 -> 184 | C10: =C46 -> 500 | D10: =D46 -> 684 | G10: priemer na 100km | I10: =IF(F7>E7,(I46/D46)*100,0) -> 9.7690058
B11: Odjazd. kilometre | E11: Stav tachometra | G11: Spotreba PHM v l. | J11: Tankovanie karta | L11: Tankovanie hotovosť | O11: Zostatok
A12: Datum | B12: mesto | C12: mimo | D12: spolu | E12: začiatoč. | F12: konečný | G12: mesto | H12: mimo | I12: spolu | J12: litre | K12: € | L12: litre | M12: € | O12: litre
A13: 1 | D13: =SUM(B13:C13) -> 0 | E13: =E7 -> 30575 | F13: =SUM(E13,D13) -> 30575 | G13: =SUM((B13*B$6)/100) -> 0 | H13: =SUM((C13*B$7)/100) -> 0 | I13: =SUM(G13:H13) -> 0 | N13: 1 | O13: =(K7-I13)+J13+L13 -> 87.11
A14: 2 | D14: =SUM(B14:C14) -> 0 | E14: =F13 -> 30575 | F14: =SUM(E14,D14) -> 30575 | G14: =SUM((B14*B$6)/100) -> 0 | H14: =SUM((C14*B$7)/100) -> 0 | I14: =SUM(G14:H14) -> 0 | N14: 2 | O14: =(O13-I14)+J14+L14 -> 87.11
A15: 3 | D15: =SUM(B15:C15) -> 0 | E15: =F14 -> 30575 | F15: =SUM(E15,D15) -> 30575 | G15: =SUM((B15*B$6)/100) -> 0 | H15: =SUM((C15*B$7)/100) -> 0 | I15: =SUM(G15:H15) -> 0 | N15: 3 | O15: =(O14-I15)+J15+L15 -> 87.11
A16: 4 | D16: =SUM(B16:C16) -> 0 | E16: =F15 -> 30575 | F16: =SUM(E16,D16) -> 30575 | G16: =SUM((B16*B$6)/100) -> 0 | H16: =SUM((C16*B$7)/100) -> 0 | I16: =SUM(G16:H16) -> 0 | N16: 4 | O16: =(O15-I16)+J16+L16 -> 87.11
A17: 5 | D17: =SUM(B17:C17) -> 0 | E17: =F16 -> 30575 | F17: =SUM(E17,D17) -> 30575 | G17: =SUM((B17*B$6)/100) -> 0 | H17: =SUM((C17*B$7)/100) -> 0 | I17: =SUM(G17:H17) -> 0 | N17: 5 | O17: =(O16-I17)+J17+L17 -> 87.11
A18: 6 | D18: =SUM(B18:C18) -> 0 | E18: =F17 -> 30575 | F18: =SUM(E18,D18) -> 30575 | G18: =SUM((B18*B$6)/100) -> 0 | H18: =SUM((C18*B$7)/100) -> 0 | I18: =SUM(G18:H18) -> 0 | N18: 6 | O18: =(O17-I18)+J18+L18 -> 87.11
A19: 7 | B19: 4 | D19: =SUM(B19:C19) -> 4 | E19: =F18 -> 30575 | F19: =SUM(E19,D19) -> 30579 | G19: =SUM((B19*B$6)/100) -> 0.42 | H19: =SUM((C19*B$7)/100) -> 0 | I19: =SUM(G19:H19) -> 0.42 | N19: 7 | O19: =(O18-I19)+J19+L19 -> 86.69
A20: 8 | D20: =SUM(B20:C20) -> 0 | E20: =F19 -> 30579 | F20: =SUM(E20,D20) -> 30579 | G20: =SUM((B20*B$6)/100) -> 0 | H20: =SUM((C20*B$7)/100) -> 0 | I20: =SUM(G20:H20) -> 0 | N20: 8 | O20: =(O19-I20)+J20+L20 -> 86.69
A21: 9 | D21: =SUM(B21:C21) -> 0 | E21: =F20 -> 30579 | F21: =SUM(E21,D21) -> 30579 | G21: =SUM((B21*B$6)/100) -> 0 | H21: =SUM((C21*B$7)/100) -> 0 | I21: =SUM(G21:H21) -> 0 | N21: 9 | O21: =(O20-I21)+J21+L21 -> 86.69
A22: 10 | D22: =SUM(B22:C22) -> 0 | E22: =F21 -> 30579 | F22: =SUM(E22,D22) -> 30579 | G22: =SUM((B22*B$6)/100) -> 0 | H22: =SUM((C22*B$7)/100) -> 0 | I22: =SUM(G22:H22) -> 0 | N22: 10 | O22: =(O21-I22)+J22+L22 -> 86.69
A23: 11 | D23: =SUM(B23:C23) -> 0 | E23: =F22 -> 30579 | F23: =SUM(E23,D23) -> 30579 | G23: =SUM((B23*B$6)/100) -> 0 | H23: =SUM((C23*B$7)/100) -> 0 | I23: =SUM(G23:H23) -> 0 | N23: 11 | O23: =(O22-I23)+J23+L23 -> 86.69
A24: 12 | D24: =SUM(B24:C24) -> 0 | E24: =F23 -> 30579 | F24: =SUM(E24,D24) -> 30579 | G24: =SUM((B24*B$6)/100) -> 0 | H24: =SUM((C24*B$7)/100) -> 0 | I24: =SUM(G24:H24) -> 0 | N24: 12 | O24: =(O23-I24)+J24+L24 -> 86.69
A25: 13 | D25: =SUM(B25:C25) -> 0 | E25: =F24 -> 30579 | F25: =SUM(E25,D25) -> 30579 | G25: =SUM((B25*B$6)/100) -> 0 | H25: =SUM((C25*B$7)/100) -> 0 | I25: =SUM(G25:H25) -> 0 | N25: 13 | O25: =(O24-I25)+J25+L25 -> 86.69
A26: 14 | D26: =SUM(B26:C26) -> 0 | E26: =F25 -> 30579 | F26: =SUM(E26,D26) -> 30579 | G26: =SUM((B26*B$6)/100) -> 0 | H26: =SUM((C26*B$7)/100) -> 0 | I26: =SUM(G26:H26) -> 0 | N26: 14 | O26: =(O25-I26)+J26+L26 -> 86.69
A27: 15 | B27: 23 | D27: =SUM(B27:C27) -> 23 | E27: =F26 -> 30579 | F27: =SUM(E27,D27) -> 30602 | G27: =SUM((B27*B$6)/100) -> 2.415 | H27: =SUM((C27*B$7)/100) -> 0 | I27: =SUM(G27:H27) -> 2.415 | N27: 15 | O27: =(O26-I27)+J27+L27 -> 84.275
A28: 16 | B28: 58 | C28: 400 | D28: =SUM(B28:C28) -> 458 | E28: =F27 -> 30602 | F28: =SUM(E28,D28) -> 31060 | G28: =SUM((B28*B$6)/100) -> 6.09 | H28: =SUM((C28*B$7)/100) -> 38 | I28: =SUM(G28:H28) -> 44.09 | N28: 16 | O28: =(O27-I28)+J28+L28 -> 40.185
A29: 17 | D29: =SUM(B29:C29) -> 0 | E29: =F28 -> 31060 | F29: =SUM(E29,D29) -> 31060 | G29: =SUM((B29*B$6)/100) -> 0 | H29: =SUM((C29*B$7)/100) -> 0 | I29: =SUM(G29:H29) -> 0 | N29: 17 | O29: =(O28-I29)+J29+L29 -> 40.185
A30: 18 | D30: =SUM(B30:C30) -> 0 | E30: =F29 -> 31060 | F30: =SUM(E30,D30) -> 31060 | G30: =SUM((B30*B$6)/100) -> 0 | H30: =SUM((C30*B$7)/100) -> 0 | I30: =SUM(G30:H30) -> 0 | N30: 18 | O30: =(O29-I30)+J30+L30 -> 40.185
A31: 19 | D31: =SUM(B31:C31) -> 0 | E31: =F30 -> 31060 | F31: =SUM(E31,D31) -> 31060 | G31: =SUM((B31*B$6)/100) -> 0 | H31: =SUM((C31*B$7)/100) -> 0 | I31: =SUM(G31:H31) -> 0 | N31: 19 | O31: =(O30-I31)+J31+L31 -> 40.185
A32: 20 | D32: =SUM(B32:C32) -> 0 | E32: =F31 -> 31060 | F32: =SUM(E32,D32) -> 31060 | G32: =SUM((B32*B$6)/100) -> 0 | H32: =SUM((C32*B$7)/100) -> 0 | I32: =SUM(G32:H32) -> 0 | N32: 20 | O32: =(O31-I32)+J32+L32 -> 40.185
A33: 21 | D33: =SUM(B33:C33) -> 0 | E33: =F32 -> 31060 | F33: =SUM(E33,D33) -> 31060 | G33: =SUM((B33*B$6)/100) -> 0 | H33: =SUM((C33*B$7)/100) -> 0 | I33: =SUM(G33:H33) -> 0 | N33: 21 | O33: =(O32-I33)+J33+L33 -> 40.185
A34: 22 | B34: 83 | C34: 100 | D34: =SUM(B34:C34) -> 183 | E34: =F33 -> 31060 | F34: =SUM(E34,D34) -> 31243 | G34: =SUM((B34*B$6)/100) -> 8.715 | H34: =SUM((C34*B$7)/100) -> 9.5 | I34: =SUM(G34:H34) -> 18.215 | N34: 22 | O34: =(O33-I34)+J34+L34 -> 21.97
A35: 23 | D35: =SUM(B35:C35) -> 0 | E35: =F34 -> 31243 | F35: =SUM(E35,D35) -> 31243 | G35: =SUM((B35*B$6)/100) -> 0 | H35: =SUM((C35*B$7)/100) -> 0 | I35: =SUM(G35:H35) -> 0 | N35: 23 | O35: =(O34-I35)+J35+L35 -> 21.97
A36: 24 | B36: 16 | D36: =SUM(B36:C36) -> 16 | E36: =F35 -> 31243 | F36: =SUM(E36,D36) -> 31259 | G36: =SUM((B36*B$6)/100) -> 1.68 | H36: =SUM((C36*B$7)/100) -> 0 | I36: =SUM(G36:H36) -> 1.68 | J36: 68 | K36: 96.83 | N36: 24 | O36: =(O35-I36)+J36+L36 -> 88.29
A37: 25 | D37: =SUM(B37:C37) -> 0 | E37: =F36 -> 31259 | F37: =SUM(E37,D37) -> 31259 | G37: =SUM((B37*B$6)/100) -> 0 | H37: =SUM((C37*B$7)/100) -> 0 | I37: =SUM(G37:H37) -> 0 | N37: 25 | O37: =(O36-I37)+J37+L37 -> 88.29
A38: 26 | D38: =SUM(B38:C38) -> 0 | E38: =F37 -> 31259 | F38: =SUM(E38,D38) -> 31259 | G38: =SUM((B38*B$6)/100) -> 0 | H38: =SUM((C38*B$7)/100) -> 0 | I38: =SUM(G38:H38) -> 0 | N38: 26 | O38: =(O37-I38)+J38+L38 -> 88.29
A39: 27 | D39: =SUM(B39:C39) -> 0 | E39: =F38 -> 31259 | F39: =SUM(E39,D39) -> 31259 | G39: =SUM((B39*B$6)/100) -> 0 | H39: =SUM((C39*B$7)/100) -> 0 | I39: =SUM(G39:H39) -> 0 | N39: 27 | O39: =(O38-I39)+J39+L39 -> 88.29
A40: 28 | D40: =SUM(B40:C40) -> 0 | E40: =F39 -> 31259 | F40: =SUM(E40,D40) -> 31259 | G40: =SUM((B40*B$6)/100) -> 0 | H40: =SUM((C40*B$7)/100) -> 0 | I40: =SUM(G40:H40) -> 0 | N40: 28 | O40: =(O39-I40)+J40+L40 -> 88.29
A41: 29 | D41: =SUM(B41:C41) -> 0 | E41: =F40 -> 31259 | F41: =SUM(E41,D41) -> 31259 | G41: =SUM((B41*B$6)/100) -> 0 | H41: =SUM((C41*B$7)/100) -> 0 | I41: =SUM(G41:H41) -> 0 | N41: 29 | O41: =(O40-I41)+J41+L41 -> 88.29
...

Sheet 05
A1: VÝKAZ VOZIDLA
A3: ='ROK Prev MV'!C4 -> BB215GN | E3: Mesiac: | F3: MAJ | H3: ='ROK Prev MV'!M2 -> 2025
A4: ='ROK Prev MV'!C5 -> dodávka | K4: Objem | L4: ='ROK Prev MV'!L5:M5 -> 90
A5: Normy | D5: STAV | E5: TACHOMETER | K5: STAV NÁDRŽ
A6: Mesto | B6: ='ROK Prev MV'!I5 -> 10.5 | E6: Začiatok | F6: Koniec | I6: Dotankovať | K6: Začiatok | L6: Koniec
A7: Vonku | B7: ='ROK Prev MV'!I4 -> 9.5 | E7: ='04'!F7 -> 31259 | F7: =F43 -> 31482 | H7: =IF(I7>0," ",IF(I7<0,"Pozor",0)) | I7: =SUM(L4-L7) -> 24.025 | J7: L | K7: ='04'!L7 -> 88.29 | L7: =O46 -> 65.975 | M7: L
K8: ='04'!L8 -> 95.08833 | L8: =L7*E50 -> 71.055075 | M8: €
B9: =IF(D10>0,B10/D10*100,0) -> 50.672646 | C9: =IF(D10>0,C10/D10*100,0) -> 49.327354 | D9: %
A10: Celkom | B10: =B46 -> 113 | C10: =C46 -> 110 | D10: =D46 -> 223 | G10: priemer na 100km | I10: =IF(F7>E7,(I46/D46)*100,0) -> 10.006726
B11: Odjazd. kilometre | E11: Stav tachometra | G11: Spotreba PHM v l. | J11: Tankovanie karta | L11: Tankovanie hotovosť | O11: Zostatok
A12: Datum | B12: mesto | C12: mimo | D12: spolu | E12: začiatoč. | F12: konečný | G12: mesto | H12: mimo | I12: spolu | J12: litre | K12: € | L12: litre | M12: € | O12: litre
A13: 1 | D13: =SUM(B13:C13) -> 0 | E13: =E7 -> 31259 | F13: =SUM(E13,D13) -> 31259 | G13: =SUM((B13*B$6)/100) -> 0 | H13: =SUM((C13*B$7)/100) -> 0 | I13: =SUM(G13:H13) -> 0 | N13: 1 | O13: =(K7-I13)+J13+L13 -> 88.29
A14: 2 | D14: =SUM(B14:C14) -> 0 | E14: =F13 -> 31259 | F14: =SUM(E14,D14) -> 31259 | G14: =SUM((B14*B$6)/100) -> 0 | H14: =SUM((C14*B$7)/100) -> 0 | I14: =SUM(G14:H14) -> 0 | N14: 2 | O14: =(O13-I14)+J14+L14 -> 88.29
A15: 3 | D15: =SUM(B15:C15) -> 0 | E15: =F14 -> 31259 | F15: =SUM(E15,D15) -> 31259 | G15: =SUM((B15*B$6)/100) -> 0 | H15: =SUM((C15*B$7)/100) -> 0 | I15: =SUM(G15:H15) -> 0 | N15: 3 | O15: =(O14-I15)+J15+L15 -> 88.29
A16: 4 | D16: =SUM(B16:C16) -> 0 | E16: =F15 -> 31259 | F16: =SUM(E16,D16) -> 31259 | G16: =SUM((B16*B$6)/100) -> 0 | H16: =SUM((C16*B$7)/100) -> 0 | I16: =SUM(G16:H16) -> 0 | N16: 4 | O16: =(O15-I16)+J16+L16 -> 88.29
A17: 5 | D17: =SUM(B17:C17) -> 0 | E17: =F16 -> 31259 | F17: =SUM(E17,D17) -> 31259 | G17: =SUM((B17*B$6)/100) -> 0 | H17: =SUM((C17*B$7)/100) -> 0 | I17: =SUM(G17:H17) -> 0 | N17: 5 | O17: =(O16-I17)+J17+L17 -> 88.29
A18: 6 | D18: =SUM(B18:C18) -> 0 | E18: =F17 -> 31259 | F18: =SUM(E18,D18) -> 31259 | G18: =SUM((B18*B$6)/100) -> 0 | H18: =SUM((C18*B$7)/100) -> 0 | I18: =SUM(G18:H18) -> 0 | N18: 6 | O18: =(O17-I18)+J18+L18 -> 88.29
A19: 7 | B19: 27 | D19: =SUM(B19:C19) -> 27 | E19: =F18 -> 31259 | F19: =SUM(E19,D19) -> 31286 | G19: =SUM((B19*B$6)/100) -> 2.835 | H19: =SUM((C19*B$7)/100) -> 0 | I19: =SUM(G19:H19) -> 2.835 | N19: 7 | O19: =(O18-I19)+J19+L19 -> 85.455
A20: 8 | D20: =SUM(B20:C20) -> 0 | E20: =F19 -> 31286 | F20: =SUM(E20,D20) -> 31286 | G20: =SUM((B20*B$6)/100) -> 0 | H20: =SUM((C20*B$7)/100) -> 0 | I20: =SUM(G20:H20) -> 0 | N20: 8 | O20: =(O19-I20)+J20+L20 -> 85.455
A21: 9 | D21: =SUM(B21:C21) -> 0 | E21: =F20 -> 31286 | F21: =SUM(E21,D21) -> 31286 | G21: =SUM((B21*B$6)/100) -> 0 | H21: =SUM((C21*B$7)/100) -> 0 | I21: =SUM(G21:H21) -> 0 | N21: 9 | O21: =(O20-I21)+J21+L21 -> 85.455
A22: 10 | D22: =SUM(B22:C22) -> 0 | E22: =F21 -> 31286 | F22: =SUM(E22,D22) -> 31286 | G22: =SUM((B22*B$6)/100) -> 0 | H22: =SUM((C22*B$7)/100) -> 0 | I22: =SUM(G22:H22) -> 0 | N22: 10 | O22: =(O21-I22)+J22+L22 -> 85.455
A23: 11 | D23: =SUM(B23:C23) -> 0 | E23: =F22 -> 31286 | F23: =SUM(E23,D23) -> 31286 | G23: =SUM((B23*B$6)/100) -> 0 | H23: =SUM((C23*B$7)/100) -> 0 | I23: =SUM(G23:H23) -> 0 | N23: 11 | O23: =(O22-I23)+J23+L23 -> 85.455
A24: 12 | D24: =SUM(B24:C24) -> 0 | E24: =F23 -> 31286 | F24: =SUM(E24,D24) -> 31286 | G24: =SUM((B24*B$6)/100) -> 0 | H24: =SUM((C24*B$7)/100) -> 0 | I24: =SUM(G24:H24) -> 0 | N24: 12 | O24: =(O23-I24)+J24+L24 -> 85.455
A25: 13 | D25: =SUM(B25:C25) -> 0 | E25: =F24 -> 31286 | F25: =SUM(E25,D25) -> 31286 | G25: =SUM((B25*B$6)/100) -> 0 | H25: =SUM((C25*B$7)/100) -> 0 | I25: =SUM(G25:H25) -> 0 | N25: 13 | O25: =(O24-I25)+J25+L25 -> 85.455
A26: 14 | B26: 20 | C26: 30 | D26: =SUM(B26:C26) -> 50 | E26: =F25 -> 31286 | F26: =SUM(E26,D26) -> 31336 | G26: =SUM((B26*B$6)/100) -> 2.1 | H26: =SUM((C26*B$7)/100) -> 2.85 | I26: =SUM(G26:H26) -> 4.95 | N26: 14 | O26: =(O25-I26)+J26+L26 -> 80.505
A27: 15 | B27: 16 | D27: =SUM(B27:C27) -> 16 | E27: =F26 -> 31336 | F27: =SUM(E27,D27) -> 31352 | G27: =SUM((B27*B$6)/100) -> 1.68 | H27: =SUM((C27*B$7)/100) -> 0 | I27: =SUM(G27:H27) -> 1.68 | N27: 15 | O27: =(O26-I27)+J27+L27 -> 78.825
A28: 16 | D28: =SUM(B28:C28) -> 0 | E28: =F27 -> 31352 | F28: =SUM(E28,D28) -> 31352 | G28: =SUM((B28*B$6)/100) -> 0 | H28: =SUM((C28*B$7)/100) -> 0 | I28: =SUM(G28:H28) -> 0 | N28: 16 | O28: =(O27-I28)+J28+L28 -> 78.825
A29: 17 | D29: =SUM(B29:C29) -> 0 | E29: =F28 -> 31352 | F29: =SUM(E29,D29) -> 31352 | G29: =SUM((B29*B$6)/100) -> 0 | H29: =SUM((C29*B$7)/100) -> 0 | I29: =SUM(G29:H29) -> 0 | N29: 17 | O29: =(O28-I29)+J29+L29 -> 78.825
A30: 18 | D30: =SUM(B30:C30) -> 0 | E30: =F29 -> 31352 | F30: =SUM(E30,D30) -> 31352 | G30: =SUM((B30*B$6)/100) -> 0 | H30: =SUM((C30*B$7)/100) -> 0 | I30: =SUM(G30:H30) -> 0 | N30: 18 | O30: =(O29-I30)+J30+L30 -> 78.825
A31: 19 | D31: =SUM(B31:C31) -> 0 | E31: =F30 -> 31352 | F31: =SUM(E31,D31) -> 31352 | G31: =SUM((B31*B$6)/100) -> 0 | H31: =SUM((C31*B$7)/100) -> 0 | I31: =SUM(G31:H31) -> 0 | N31: 19 | O31: =(O30-I31)+J31+L31 -> 78.825
A32: 20 | D32: =SUM(B32:C32) -> 0 | E32: =F31 -> 31352 | F32: =SUM(E32,D32) -> 31352 | G32: =SUM((B32*B$6)/100) -> 0 | H32: =SUM((C32*B$7)/100) -> 0 | I32: =SUM(G32:H32) -> 0 | N32: 20 | O32: =(O31-I32)+J32+L32 -> 78.825
A33: 21 | B33: 40 | C33: 80 | D33: =SUM(B33:C33) -> 120 | E33: =F32 -> 31352 | F33: =SUM(E33,D33) -> 31472 | G33: =SUM((B33*B$6)/100) -> 4.2 | H33: =SUM((C33*B$7)/100) -> 7.6 | I33: =SUM(G33:H33) -> 11.8 | N33: 21 | O33: =(O32-I33)+J33+L33 -> 67.025
A34: 22 | D34: =SUM(B34:C34) -> 0 | E34: =F33 -> 31472 | F34: =SUM(E34,D34) -> 31472 | G34: =SUM((B34*B$6)/100) -> 0 | H34: =SUM((C34*B$7)/100) -> 0 | I34: =SUM(G34:H34) -> 0 | N34: 22 | O34: =(O33-I34)+J34+L34 -> 67.025
A35: 23 | B35: 10 | D35: =SUM(B35:C35) -> 10 | E35: =F34 -> 31472 | F35: =SUM(E35,D35) -> 31482 | G35: =SUM((B35*B$6)/100) -> 1.05 | H35: =SUM((C35*B$7)/100) -> 0 | I35: =SUM(G35:H35) -> 1.05 | N35: 23 | O35: =(O34-I35)+J35+L35 -> 65.975
A36: 24 | D36: =SUM(B36:C36) -> 0 | E36: =F35 -> 31482 | F36: =SUM(E36,D36) -> 31482 | G36: =SUM((B36*B$6)/100) -> 0 | H36: =SUM((C36*B$7)/100) -> 0 | I36: =SUM(G36:H36) -> 0 | N36: 24 | O36: =(O35-I36)+J36+L36 -> 65.975
A37: 25 | D37: =SUM(B37:C37) -> 0 | E37: =F36 -> 31482 | F37: =SUM(E37,D37) -> 31482 | G37: =SUM((B37*B$6)/100) -> 0 | H37: =SUM((C37*B$7)/100) -> 0 | I37: =SUM(G37:H37) -> 0 | N37: 25 | O37: =(O36-I37)+J37+L37 -> 65.975
A38: 26 | D38: =SUM(B38:C38) -> 0 | E38: =F37 -> 31482 | F38: =SUM(E38,D38) -> 31482 | G38: =SUM((B38*B$6)/100) -> 0 | H38: =SUM((C38*B$7)/100) -> 0 | I38: =SUM(G38:H38) -> 0 | N38: 26 | O38: =(O37-I38)+J38+L38 -> 65.975
A39: 27 | D39: =SUM(B39:C39) -> 0 | E39: =F38 -> 31482 | F39: =SUM(E39,D39) -> 31482 | G39: =SUM((B39*B$6)/100) -> 0 | H39: =SUM((C39*B$7)/100) -> 0 | I39: =SUM(G39:H39) -> 0 | N39: 27 | O39: =(O38-I39)+J39+L39 -> 65.975
A40: 28 | D40: =SUM(B40:C40) -> 0 | E40: =F39 -> 31482 | F40: =SUM(E40,D40) -> 31482 | G40: =SUM((B40*B$6)/100) -> 0 | H40: =SUM((C40*B$7)/100) -> 0 | I40: =SUM(G40:H40) -> 0 | N40: 28 | O40: =(O39-I40)+J40+L40 -> 65.975
A41: 29 | D41: =SUM(B41:C41) -> 0 | E41: =F40 -> 31482 | F41: =SUM(E41,D41) -> 31482 | G41: =SUM((B41*B$6)/100) -> 0 | H41: =SUM((C41*B$7)/100) -> 0 | I41: =SUM(G41:H41) -> 0 | N41: 29 | O41: =(O40-I41)+J41+L41 -> 65.975
...

Sheet 06
A1: VÝKAZ VOZIDLA
A3: ='ROK Prev MV'!C4 -> BB215GN | E3: Mesiac: | F3: JUN | H3: ='ROK Prev MV'!M2 -> 2025
A4: ='ROK Prev MV'!C5 -> dodávka | K4: Objem | L4: ='ROK Prev MV'!L5:M5 -> 90
A5: Normy | D5: STAV | E5: TACHOMETER | K5: STAV NÁDRŽ
A6: Mesto | B6: ='ROK Prev MV'!I5 -> 10.5 | E6: Začiatok | F6: Koniec | I6: Dotankovať | K6: Začiatok | L6: Koniec
A7: Vonku | B7: ='ROK Prev MV'!I4 -> 9.5 | E7: ='05'!F7 -> 31482 | F7: =F43 -> 31565 | H7: =IF(I7>0," ",IF(I7<0,"Pozor",0)) | I7: =SUM(L4-L7) -> 32.74 | J7: L | K7: ='05'!L7 -> 65.975 | L7: =O46 -> 57.26 | M7: L
K8: ='05'!L8 -> 71.055075 | L8: =L7*E50 -> 61.66902 | M8: €
B9: =IF(D10>0,B10/D10*100,0) -> 100 | C9: =IF(D10>0,C10/D10*100,0) -> 0 | D9: %
A10: Celkom | B10: =B46 -> 83 | C10: =C46 -> 0 | D10: =D46 -> 83 | G10: priemer na 100km | I10: =IF(F7>E7,(I46/D46)*100,0) -> 10.5
B11: Odjazd. kilometre | E11: Stav tachometra | G11: Spotreba PHM v l. | J11: Tankovanie karta | L11: Tankovanie hotovosť | O11: Zostatok
A12: Datum | B12: mesto | C12: mimo | D12: spolu | E12: začiatoč. | F12: konečný | G12: mesto | H12: mimo | I12: spolu | J12: litre | K12: € | L12: litre | M12: € | O12: litre
A13: 1 | D13: =SUM(B13:C13) -> 0 | E13: =E7 -> 31482 | F13: =SUM(E13,D13) -> 31482 | G13: =SUM((B13*B$6)/100) -> 0 | H13: =SUM((C13*B$7)/100) -> 0 | I13: =SUM(G13:H13) -> 0 | N13: 1 | O13: =(K7-I13)+J13+L13 -> 65.975
A14: 2 | D14: =SUM(B14:C14) -> 0 | E14: =F13 -> 31482 | F14: =SUM(E14,D14) -> 31482 | G14: =SUM((B14*B$6)/100) -> 0 | H14: =SUM((C14*B$7)/100) -> 0 | I14: =SUM(G14:H14) -> 0 | N14: 2 | O14: =(O13-I14)+J14+L14 -> 65.975
A15: 3 | D15: =SUM(B15:C15) -> 0 | E15: =F14 -> 31482 | F15: =SUM(E15,D15) -> 31482 | G15: =SUM((B15*B$6)/100) -> 0 | H15: =SUM((C15*B$7)/100) -> 0 | I15: =SUM(G15:H15) -> 0 | N15: 3 | O15: =(O14-I15)+J15+L15 -> 65.975
A16: 4 | D16: =SUM(B16:C16) -> 0 | E16: =F15 -> 31482 | F16: =SUM(E16,D16) -> 31482 | G16: =SUM((B16*B$6)/100) -> 0 | H16: =SUM((C16*B$7)/100) -> 0 | I16: =SUM(G16:H16) -> 0 | N16: 4 | O16: =(O15-I16)+J16+L16 -> 65.975
A17: 5 | D17: =SUM(B17:C17) -> 0 | E17: =F16 -> 31482 | F17: =SUM(E17,D17) -> 31482 | G17: =SUM((B17*B$6)/100) -> 0 | H17: =SUM((C17*B$7)/100) -> 0 | I17: =SUM(G17:H17) -> 0 | N17: 5 | O17: =(O16-I17)+J17+L17 -> 65.975
A18: 6 | B18: 10 | D18: =SUM(B18:C18) -> 10 | E18: =F17 -> 31482 | F18: =SUM(E18,D18) -> 31492 | G18: =SUM((B18*B$6)/100) -> 1.05 | H18: =SUM((C18*B$7)/100) -> 0 | I18: =SUM(G18:H18) -> 1.05 | N18: 6 | O18: =(O17-I18)+J18+L18 -> 64.925
A19: 7 | D19: =SUM(B19:C19) -> 0 | E19: =F18 -> 31492 | F19: =SUM(E19,D19) -> 31492 | G19: =SUM((B19*B$6)/100) -> 0 | H19: =SUM((C19*B$7)/100) -> 0 | I19: =SUM(G19:H19) -> 0 | N19: 7 | O19: =(O18-I19)+J19+L19 -> 64.925
A20: 8 | D20: =SUM(B20:C20) -> 0 | E20: =F19 -> 31492 | F20: =SUM(E20,D20) -> 31492 | G20: =SUM((B20*B$6)/100) -> 0 | H20: =SUM((C20*B$7)/100) -> 0 | I20: =SUM(G20:H20) -> 0 | N20: 8 | O20: =(O19-I20)+J20+L20 -> 64.925
A21: 9 | D21: =SUM(B21:C21) -> 0 | E21: =F20 -> 31492 | F21: =SUM(E21,D21) -> 31492 | G21: =SUM((B21*B$6)/100) -> 0 | H21: =SUM((C21*B$7)/100) -> 0 | I21: =SUM(G21:H21) -> 0 | N21: 9 | O21: =(O20-I21)+J21+L21 -> 64.925
A22: 10 | B22: 35 | D22: =SUM(B22:C22) -> 35 | E22: =F21 -> 31492 | F22: =SUM(E22,D22) -> 31527 | G22: =SUM((B22*B$6)/100) -> 3.675 | H22: =SUM((C22*B$7)/100) -> 0 | I22: =SUM(G22:H22) -> 3.675 | N22: 10 | O22: =(O21-I22)+J22+L22 -> 61.25
A23: 11 | D23: =SUM(B23:C23) -> 0 | E23: =F22 -> 31527 | F23: =SUM(E23,D23) -> 31527 | G23: =SUM((B23*B$6)/100) -> 0 | H23: =SUM((C23*B$7)/100) -> 0 | I23: =SUM(G23:H23) -> 0 | N23: 11 | O23: =(O22-I23)+J23+L23 -> 61.25
A24: 12 | D24: =SUM(B24:C24) -> 0 | E24: =F23 -> 31527 | F24: =SUM(E24,D24) -> 31527 | G24: =SUM((B24*B$6)/100) -> 0 | H24: =SUM((C24*B$7)/100) -> 0 | I24: =SUM(G24:H24) -> 0 | N24: 12 | O24: =(O23-I24)+J24+L24 -> 61.25
A25: 13 | D25: =SUM(B25:C25) -> 0 | E25: =F24 -> 31527 | F25: =SUM(E25,D25) -> 31527 | G25: =SUM((B25*B$6)/100) -> 0 | H25: =SUM((C25*B$7)/100) -> 0 | I25: =SUM(G25:H25) -> 0 | N25: 13 | O25: =(O24-I25)+J25+L25 -> 61.25
A26: 14 | D26: =SUM(B26:C26) -> 0 | E26: =F25 -> 31527 | F26: =SUM(E26,D26) -> 31527 | G26: =SUM((B26*B$6)/100) -> 0 | H26: =SUM((C26*B$7)/100) -> 0 | I26: =SUM(G26:H26) -> 0 | N26: 14 | O26: =(O25-I26)+J26+L26 -> 61.25
A27: 15 | D27: =SUM(B27:C27) -> 0 | E27: =F26 -> 31527 | F27: =SUM(E27,D27) -> 31527 | G27: =SUM((B27*B$6)/100) -> 0 | H27: =SUM((C27*B$7)/100) -> 0 | I27: =SUM(G27:H27) -> 0 | N27: 15 | O27: =(O26-I27)+J27+L27 -> 61.25
A28: 16 | D28: =SUM(B28:C28) -> 0 | E28: =F27 -> 31527 | F28: =SUM(E28,D28) -> 31527 | G28: =SUM((B28*B$6)/100) -> 0 | H28: =SUM((C28*B$7)/100) -> 0 | I28: =SUM(G28:H28) -> 0 | N28: 16 | O28: =(O27-I28)+J28+L28 -> 61.25
A29: 17 | D29: =SUM(B29:C29) -> 0 | E29: =F28 -> 31527 | F29: =SUM(E29,D29) -> 31527 | G29: =SUM((B29*B$6)/100) -> 0 | H29: =SUM((C29*B$7)/100) -> 0 | I29: =SUM(G29:H29) -> 0 | N29: 17 | O29: =(O28-I29)+J29+L29 -> 61.25
A30: 18 | D30: =SUM(B30:C30) -> 0 | E30: =F29 -> 31527 | F30: =SUM(E30,D30) -> 31527 | G30: =SUM((B30*B$6)/100) -> 0 | H30: =SUM((C30*B$7)/100) -> 0 | I30: =SUM(G30:H30) -> 0 | N30: 18 | O30: =(O29-I30)+J30+L30 -> 61.25
A31: 19 | D31: =SUM(B31:C31) -> 0 | E31: =F30 -> 31527 | F31: =SUM(E31,D31) -> 31527 | G31: =SUM((B31*B$6)/100) -> 0 | H31: =SUM((C31*B$7)/100) -> 0 | I31: =SUM(G31:H31) -> 0 | N31: 19 | O31: =(O30-I31)+J31+L31 -> 61.25
A32: 20 | D32: =SUM(B32:C32) -> 0 | E32: =F31 -> 31527 | F32: =SUM(E32,D32) -> 31527 | G32: =SUM((B32*B$6)/100) -> 0 | H32: =SUM((C32*B$7)/100) -> 0 | I32: =SUM(G32:H32) -> 0 | N32: 20 | O32: =(O31-I32)+J32+L32 -> 61.25
A33: 21 | D33: =SUM(B33:C33) -> 0 | E33: =F32 -> 31527 | F33: =SUM(E33,D33) -> 31527 | G33: =SUM((B33*B$6)/100) -> 0 | H33: =SUM((C33*B$7)/100) -> 0 | I33: =SUM(G33:H33) -> 0 | N33: 21 | O33: =(O32-I33)+J33+L33 -> 61.25
A34: 22 | D34: =SUM(B34:C34) -> 0 | E34: =F33 -> 31527 | F34: =SUM(E34,D34) -> 31527 | G34: =SUM((B34*B$6)/100) -> 0 | H34: =SUM((C34*B$7)/100) -> 0 | I34: =SUM(G34:H34) -> 0 | N34: 22 | O34: =(O33-I34)+J34+L34 -> 61.25
A35: 23 | B35: 19 | D35: =SUM(B35:C35) -> 19 | E35: =F34 -> 31527 | F35: =SUM(E35,D35) -> 31546 | G35: =SUM((B35*B$6)/100) -> 1.995 | H35: =SUM((C35*B$7)/100) -> 0 | I35: =SUM(G35:H35) -> 1.995 | N35: 23 | O35: =(O34-I35)+J35+L35 -> 59.255
A36: 24 | D36: =SUM(B36:C36) -> 0 | E36: =F35 -> 31546 | F36: =SUM(E36,D36) -> 31546 | G36: =SUM((B36*B$6)/100) -> 0 | H36: =SUM((C36*B$7)/100) -> 0 | I36: =SUM(G36:H36) -> 0 | N36: 24 | O36: =(O35-I36)+J36+L36 -> 59.255
A37: 25 | D37: =SUM(B37:C37) -> 0 | E37: =F36 -> 31546 | F37: =SUM(E37,D37) -> 31546 | G37: =SUM((B37*B$6)/100) -> 0 | H37: =SUM((C37*B$7)/100) -> 0 | I37: =SUM(G37:H37) -> 0 | N37: 25 | O37: =(O36-I37)+J37+L37 -> 59.255
A38: 26 | D38: =SUM(B38:C38) -> 0 | E38: =F37 -> 31546 | F38: =SUM(E38,D38) -> 31546 | G38: =SUM((B38*B$6)/100) -> 0 | H38: =SUM((C38*B$7)/100) -> 0 | I38: =SUM(G38:H38) -> 0 | N38: 26 | O38: =(O37-I38)+J38+L38 -> 59.255
A39: 27 | D39: =SUM(B39:C39) -> 0 | E39: =F38 -> 31546 | F39: =SUM(E39,D39) -> 31546 | G39: =SUM((B39*B$6)/100) -> 0 | H39: =SUM((C39*B$7)/100) -> 0 | I39: =SUM(G39:H39) -> 0 | N39: 27 | O39: =(O38-I39)+J39+L39 -> 59.255
A40: 28 | D40: =SUM(B40:C40) -> 0 | E40: =F39 -> 31546 | F40: =SUM(E40,D40) -> 31546 | G40: =SUM((B40*B$6)/100) -> 0 | H40: =SUM((C40*B$7)/100) -> 0 | I40: =SUM(G40:H40) -> 0 | N40: 28 | O40: =(O39-I40)+J40+L40 -> 59.255
A41: 29 | D41: =SUM(B41:C41) -> 0 | E41: =F40 -> 31546 | F41: =SUM(E41,D41) -> 31546 | G41: =SUM((B41*B$6)/100) -> 0 | H41: =SUM((C41*B$7)/100) -> 0 | I41: =SUM(G41:H41) -> 0 | N41: 29 | O41: =(O40-I41)+J41+L41 -> 59.255
...

Sheet 07
A1: VÝKAZ VOZIDLA
A3: ='ROK Prev MV'!C4 -> BB215GN | E3: Mesiac: | F3: JUL | H3: ='ROK Prev MV'!M2 -> 2025
A4: ='ROK Prev MV'!C5 -> dodávka | K4: Objem | L4: ='ROK Prev MV'!L5:M5 -> 90
A5: Normy | D5: STAV | E5: TACHOMETER | K5: STAV NÁDRŽ
A6: Mesto | B6: ='ROK Prev MV'!I5 -> 10.5 | E6: Začiatok | F6: Koniec | I6: Dotankovať | K6: Začiatok | L6: Koniec
A7: Vonku | B7: ='ROK Prev MV'!I4 -> 9.5 | E7: ='06'!F7 -> 31565 | F7: =F43 -> 31648 | H7: =IF(I7>0," ",IF(I7<0,"Pozor",0)) | I7: =SUM(L4-L7) -> 41.355 | J7: L | K7: ='06'!L7 -> 57.26 | L7: =O46 -> 48.645 | M7: L
K8: ='06'!L8 -> 61.66902 | L8: =L7*E50 -> 52.390665 | M8: €
B9: =IF(D10>0,B10/D10*100,0) -> 87.951807 | C9: =IF(D10>0,C10/D10*100,0) -> 12.048193 | D9: %
A10: Celkom | B10: =B46 -> 73 | C10: =C46 -> 10 | D10: =D46 -> 83 | G10: priemer na 100km | I10: =IF(F7>E7,(I46/D46)*100,0) -> 10.379518
B11: Odjazd. kilometre | E11: Stav tachometra | G11: Spotreba PHM v l. | J11: Tankovanie karta | L11: Tankovanie hotovosť | O11: Zostatok
A12: Datum | B12: mesto | C12: mimo | D12: spolu | E12: začiatoč. | F12: konečný | G12: mesto | H12: mimo | I12: spolu | J12: litre | K12: € | L12: litre | M12: € | O12: litre
A13: 1 | D13: =SUM(B13:C13) -> 0 | E13: =E7 -> 31565 | F13: =SUM(E13,D13) -> 31565 | G13: =SUM((B13*B$6)/100) -> 0 | H13: =SUM((C13*B$7)/100) -> 0 | I13: =SUM(G13:H13) -> 0 | N13: 1 | O13: =(K7-I13)+J13+L13 -> 57.26
A14: 2 | D14: =SUM(B14:C14) -> 0 | E14: =F13 -> 31565 | F14: =SUM(E14,D14) -> 31565 | G14: =SUM((B14*B$6)/100) -> 0 | H14: =SUM((C14*B$7)/100) -> 0 | I14: =SUM(G14:H14) -> 0 | N14: 2 | O14: =(O13-I14)+J14+L14 -> 57.26
A15: 3 | B15: 39 | D15: =SUM(B15:C15) -> 39 | E15: =F14 -> 31565 | F15: =SUM(E15,D15) -> 31604 | G15: =SUM((B15*B$6)/100) -> 4.095 | H15: =SUM((C15*B$7)/100) -> 0 | I15: =SUM(G15:H15) -> 4.095 | N15: 3 | O15: =(O14-I15)+J15+L15 -> 53.165
A16: 4 | D16: =SUM(B16:C16) -> 0 | E16: =F15 -> 31604 | F16: =SUM(E16,D16) -> 31604 | G16: =SUM((B16*B$6)/100) -> 0 | H16: =SUM((C16*B$7)/100) -> 0 | I16: =SUM(G16:H16) -> 0 | N16: 4 | O16: =(O15-I16)+J16+L16 -> 53.165
A17: 5 | D17: =SUM(B17:C17) -> 0 | E17: =F16 -> 31604 | F17: =SUM(E17,D17) -> 31604 | G17: =SUM((B17*B$6)/100) -> 0 | H17: =SUM((C17*B$7)/100) -> 0 | I17: =SUM(G17:H17) -> 0 | N17: 5 | O17: =(O16-I17)+J17+L17 -> 53.165
A18: 6 | D18: =SUM(B18:C18) -> 0 | E18: =F17 -> 31604 | F18: =SUM(E18,D18) -> 31604 | G18: =SUM((B18*B$6)/100) -> 0 | H18: =SUM((C18*B$7)/100) -> 0 | I18: =SUM(G18:H18) -> 0 | N18: 6 | O18: =(O17-I18)+J18+L18 -> 53.165
A19: 7 | D19: =SUM(B19:C19) -> 0 | E19: =F18 -> 31604 | F19: =SUM(E19,D19) -> 31604 | G19: =SUM((B19*B$6)/100) -> 0 | H19: =SUM((C19*B$7)/100) -> 0 | I19: =SUM(G19:H19) -> 0 | N19: 7 | O19: =(O18-I19)+J19+L19 -> 53.165
A20: 8 | D20: =SUM(B20:C20) -> 0 | E20: =F19 -> 31604 | F20: =SUM(E20,D20) -> 31604 | G20: =SUM((B20*B$6)/100) -> 0 | H20: =SUM((C20*B$7)/100) -> 0 | I20: =SUM(G20:H20) -> 0 | N20: 8 | O20: =(O19-I20)+J20+L20 -> 53.165
A21: 9 | D21: =SUM(B21:C21) -> 0 | E21: =F20 -> 31604 | F21: =SUM(E21,D21) -> 31604 | G21: =SUM((B21*B$6)/100) -> 0 | H21: =SUM((C21*B$7)/100) -> 0 | I21: =SUM(G21:H21) -> 0 | N21: 9 | O21: =(O20-I21)+J21+L21 -> 53.165
A22: 10 | D22: =SUM(B22:C22) -> 0 | E22: =F21 -> 31604 | F22: =SUM(E22,D22) -> 31604 | G22: =SUM((B22*B$6)/100) -> 0 | H22: =SUM((C22*B$7)/100) -> 0 | I22: =SUM(G22:H22) -> 0 | N22: 10 | O22: =(O21-I22)+J22+L22 -> 53.165
A23: 11 | D23: =SUM(B23:C23) -> 0 | E23: =F22 -> 31604 | F23: =SUM(E23,D23) -> 31604 | G23: =SUM((B23*B$6)/100) -> 0 | H23: =SUM((C23*B$7)/100) -> 0 | I23: =SUM(G23:H23) -> 0 | N23: 11 | O23: =(O22-I23)+J23+L23 -> 53.165
A24: 12 | D24: =SUM(B24:C24) -> 0 | E24: =F23 -> 31604 | F24: =SUM(E24,D24) -> 31604 | G24: =SUM((B24*B$6)/100) -> 0 | H24: =SUM((C24*B$7)/100) -> 0 | I24: =SUM(G24:H24) -> 0 | N24: 12 | O24: =(O23-I24)+J24+L24 -> 53.165
A25: 13 | D25: =SUM(B25:C25) -> 0 | E25: =F24 -> 31604 | F25: =SUM(E25,D25) -> 31604 | G25: =SUM((B25*B$6)/100) -> 0 | H25: =SUM((C25*B$7)/100) -> 0 | I25: =SUM(G25:H25) -> 0 | N25: 13 | O25: =(O24-I25)+J25+L25 -> 53.165
A26: 14 | D26: =SUM(B26:C26) -> 0 | E26: =F25 -> 31604 | F26: =SUM(E26,D26) -> 31604 | G26: =SUM((B26*B$6)/100) -> 0 | H26: =SUM((C26*B$7)/100) -> 0 | I26: =SUM(G26:H26) -> 0 | N26: 14 | O26: =(O25-I26)+J26+L26 -> 53.165
A27: 15 | D27: =SUM(B27:C27) -> 0 | E27: =F26 -> 31604 | F27: =SUM(E27,D27) -> 31604 | G27: =SUM((B27*B$6)/100) -> 0 | H27: =SUM((C27*B$7)/100) -> 0 | I27: =SUM(G27:H27) -> 0 | N27: 15 | O27: =(O26-I27)+J27+L27 -> 53.165
... A35: 23 | D35: =SUM(B35:C35) -> 0 | E35: =F34 -> 31604 | F35: =SUM(E35,D35) -> 31604 | G35: =SUM((B35*B$6)/100) -> 0 | H35: =SUM((C35*B$7)/100) -> 0 | I35: =SUM(G35:H35) -> 0 | N35: 23 | O35: =(O34-I35)+J35+L35 -> 53.165
A36: 24 | B36: 34 | C36: 10 | D36: =SUM(B36:C36) -> 44 | E36: =F35 -> 31604 | F36: =SUM(E36,D36) -> 31648 | G36: =SUM((B36*B$6)/100) -> 3.57 | H36: =SUM((C36*B$7)/100) -> 0.95 | I36: =SUM(G36:H36) -> 4.52 | N36: 24 | O36: =(O35-I36)+J36+L36 -> 48.645
A37: 25 | D37: =SUM(B37:C37) -> 0 | E37: =F36 -> 31648 | F37: =SUM(E37,D37) -> 31648 | G37: =SUM((B37*B$6)/100) -> 0 | H37: =SUM((C37*B$7)/100) -> 0 | I37: =SUM(G37:H37) -> 0 | N37: 25 | O37: =(O36-I37)+J37+L37 -> 48.645
A38: 26 | D38: =SUM(B38:C38) -> 0 | E38: =F37 -> 31648 | F38: =SUM(E38,D38) -> 31648 | G38: =SUM((B38*B$6)/100) -> 0 | H38: =SUM((C38*B$7)/100) -> 0 | I38: =SUM(G38:H38) -> 0 | N38: 26 | O38: =(O37-I38)+J38+L38 -> 48.645
A39: 27 | D39: =SUM(B39:C39) -> 0 | E39: =F38 -> 31648 | F39: =SUM(E39,D39) -> 31648 | G39: =SUM((B39*B$6)/100) -> 0 | H39: =SUM((C39*B$7)/100) -> 0 | I39: =SUM(G39:H39) -> 0 | N39: 27 | O39: =(O38-I39)+J39+L39 -> 48.645
A40: 28 | D40: =SUM(B40:C40) -> 0 | E40: =F39 -> 31648 | F40: =SUM(E40,D40) -> 31648 | G40: =SUM((B40*B$6)/100) -> 0 | H40: =SUM((C40*B$7)/100) -> 0 | I40: =SUM(G40:H40) -> 0 | N40: 28 | O40: =(O39-I40)+J40+L40 -> 48.645
A41: 29 | D41: =SUM(B41:C41) -> 0 | E41: =F40 -> 31648 | F41: =SUM(E41,D41) -> 31648 | G41: =SUM((B41*B$6)/100) -> 0 | H41: =SUM((C41*B$7)/100) -> 0 | I41: =SUM(G41:H41) -> 0 | N41: 29 | O41: =(O40-I41)+J41+L41 -> 48.645
A42: 30 | D42: =SUM(B42:C42) -> 0 | E42: =F41 -> 31648 | F42: =SUM(E42,D42) -> 31648 | G42: =SUM((B42*B$6)/100) -> 0 | H42: =SUM((C42*B$7)/100) -> 0 | I42: =SUM(G42:H42) -> 0 | N42: 30 | O42: =(O41-I42)+J42+L42 -> 48.645
A43: 31 | D43: =SUM(B43:C43) -> 0 | E43: =F42 -> 31648 | F43: =SUM(E43,D43) -> 31648 | G43: =SUM((B43*B$6)/100) -> 0 | H43: =SUM((C43*B$7)/100) -> 0 | I43: =SUM(G43:H43) -> 0 | N43: 31 | O43: =(O42-I43)+J43+L43 -> 48.645
B44: Odjazd. kilometre | E44: Stav tachometra | G44: Spotreba PHM v l. | J44: Tankovanie karta | L44: Tankovanie hotovosť | O44: Zostatok
A45: Datum | B45: mesto | C45: mimo | D45: spolu | E45: začiatoč. | F45: konečný | G45: mesto | H45: mimo | I45: spolu | J45: litre | K45: € | L45: litre | M45: € | O45: litre
B46: =SUM(B13:B43) -> 73 | C46: =SUM(C13:C43) -> 10 | D46: =SUM(D13:D43) -> 83 | E46: =E7 -> 31565 | F46: =F43 -> 31648 | G46: =SUM(G13:G43) -> 7.665 | H46: =SUM(H13:H43) -> 0.95 | I46: =SUM(I13:I43) -> 8.615 | J46: =SUM(J13:J43) -> 0 | K46: =SUM(K13:K43) -> 0 | L46: =SUM(L13:L43) -> 0 | M46: =SUM(M13:M43) -> 0 | O46: =O43 -> 48.645
C48: Palivo | E48: Priemerná cena | G48: Spotreba PHM v €. | J48: Tankovanie celkom
E49: za liter PHM | G49: mesto | H49: mimo | I49: spolu | J49: litre | K49: €
...

Sheet 08
A1: VÝKAZ VOZIDLA
A3: ='ROK Prev MV'!C4 -> BB215GN | E3: Mesiac: | F3: AUGUST | H3: ='ROK Prev MV'!M2 -> 2025
A4: ='ROK Prev MV'!C5 -> dodávka | K4: Objem | L4: ='ROK Prev MV'!L5:M5 -> 90
A5: Normy | D5: STAV | E5: TACHOMETER | K5: STAV NÁDRŽ
A6: Mesto | B6: ='ROK Prev MV'!I5 -> 10.5 | E6: Začiatok | F6: Koniec | I6: Dotankovať | K6: Začiatok | L6: Koniec
A7: Vonku | B7: ='ROK Prev MV'!I4 -> 9.5 | E7: ='07'!F7 -> 31648 | F7: =F43 -> 32620 | H7: =IF(I7>0," ",IF(I7<0,"Pozor",0)) | I7: =SUM(L4-L7) -> 1.335 | J7: L | K7: ='07'!L7 -> 48.645 | L7: =O46 -> 88.665 | M7: L
K8: ='07'!L8 -> 52.390665 | L8: =L7*E50 -> 86.18238 | M8: €
B9: =IF(D10>0,B10/D10*100,0) -> 32.304527 | C9: =IF(D10>0,C10/D10*100,0) -> 67.695473 | D9: %
A10: Celkom | B10: =B46 -> 314 | C10: =C46 -> 658 | D10: =D46 -> 972 | G10: priemer na 100km | I10: =IF(F7>E7,(I46/D46)*100,0) -> 9.8230453
